<?xml version="1.0"?>
<robot xmlns:xacro="http://ros.org/wiki/xacro" >

   <xacro:macro name="sara_arm_v2" params="prefix parent *origin sim">
     <xacro:if value="${sim}">
       <xacro:include filename="$(find sara_description)/urdf/arm_v2/arm.gazebo.xacro" />
       <xacro:sara_arm_gazebo_v2 prefix="${prefix}"/>
     </xacro:if>
     <xacro:include filename="$(find sara_description)/urdf/arm_v2/arm.transmission.xacro" />
     <xacro:sara_arm_transmission_v2 prefix="${prefix}"/>

     <joint name="${prefix}shoulder_roll_joint" type="revolute">
       <parent link="${parent}_link"/>
       <child link="${prefix}clavicular_link"/>
       <limit effort="1000.0" lower="-1.6" upper="1.4" velocity="0.5"/>
       <xacro:insert_block name="origin"/>
       <axis xyz="0 0 1" />
     </joint>

     <link name="${prefix}clavicular_link">
       <visual>
         <geometry>
           <mesh filename="package://sara_description/meshes/epaule1.STL" scale="0.001 0.001 0.001"/>
         </geometry>
         <origin xyz="0 0 0" rpy="0 0 0"/>
         <material name="black">
           <color rgba="0.12 0.12 0.12 1"/>
         </material>
       </visual>
       <collision>
         <geometry>
           <mesh filename="package://sara_description/meshes/epaule1.STL" scale="0.001 0.001 0.001"/>
         </geometry>
           <origin xyz="0 0 0" rpy="0 3.1416 0"/>
       </collision>
       <inertial>
         <mass value="1" />
         <origin xyz="0 -0.05029668 0.01842530" rpy="0 3.1416 0" />
         <inertia ixx = "0.00040675" ixy="0.0" ixz="0.0"
                  iyy = "0.00039956" iyz = "0.00003451"
                  izz = "0.00059825" />
       </inertial>
     </link>

     <joint name="${prefix}shoulder_pitch_joint" type="revolute">
       <parent link="${prefix}clavicular_link"/>
       <child link="${prefix}upper_arm_upper_link"/>
       <limit effort="1000.0" lower="-4.7124" upper="1.5708" velocity="0.5"/>
       <origin xyz="0 -0.085 0" rpy="-1.57 0 0" />
       <axis xyz="0 0 1" />
     </joint>

     <link name="${prefix}upper_arm_upper_link">
       <visual>
         <geometry>
           <mesh filename="package://sara_description/meshes/epaule2.STL" scale="0.001 0.001 0.001"/>
         </geometry>
           <origin xyz="0 0 0" rpy="0 0 0"/>
           <material name="black">
             <color rgba="0.12 0.12 0.12 1"/>
           </material>
       </visual>
       <collision>
         <geometry>
           <mesh filename="package://sara_description/meshes/epaule2.STL" scale="0.001 0.001 0.001"/>
         </geometry>
           <origin xyz="0 0 0" rpy="0 0 0"/>
         </collision>
         <inertial>
           <mass value="1" />
           <origin xyz="0 0 0" rpy="3.1416 0 1.5708"/>
           <inertia ixx="0.001" ixy="0" ixz="0" iyy="0.001" iyz="0" izz="0.001" />
         </inertial>
     </link>

     <joint name="${prefix}shoulder_yaw_joint" type="revolute">
       <parent link="${prefix}upper_arm_upper_link"/>
       <child link="${prefix}upper_arm_lower_link"/>
       <limit effort="1000.0" lower="-3.1416" upper="3.1416" velocity="0.5"/>
       <origin xyz="-0.085 0 0" rpy="1.5708 0 1.5708" />
       <axis xyz="0 0 1" />
     </joint>

     <link name="${prefix}upper_arm_lower_link">
       <visual>
         <geometry>
           <mesh filename="package://sara_description/meshes/bras_haut.STL" scale="0.001 0.001 0.001"/>
         </geometry>
         <origin xyz="0 0 0" rpy="0 0 0"/>
         <material name="black">
           <color rgba="0.12 0.12 0.12 1"/>
         </material>
       </visual>
       <collision>
         <geometry>
           <mesh filename="package://sara_description/meshes/bras_haut.STL" scale="0.001 0.001 0.001"/>
         </geometry>
         <origin xyz="0 0 0" rpy="1.5708 3.1416 3.1416"/>
       </collision>
       <inertial>
         <mass value="1" />
         <origin xyz="0 0 0" rpy="1.5708 3.1416 3.1416"/>
         <inertia ixx = "0.02042044" ixy="-0.00028692" ixz="-0.00000813"
                  iyy="0.00056723" iyz="0.00027077"
                  izz="0.02071076" />
       </inertial>
     </link>

      <joint name="${prefix}elbow_pitch_joint" type="revolute">
        <parent link="${prefix}upper_arm_lower_link"/>
        <child link="${prefix}forearm_upper_link"/>
        <limit effort="1000.0" lower="-2.20" upper="1.90" velocity="0.5"/>
        <origin xyz="0 0 -0.31" rpy="-1.5708 0 0" />
        <axis xyz="0 0 1" />
      </joint>

      <link name="${prefix}forearm_upper_link">
        <visual>
          <geometry>
            <mesh filename="package://sara_description/meshes/coude.STL" scale="0.001 0.001 0.001"/>
          </geometry>
            <origin xyz="0 0 -0.0005" rpy="0 0 0"/>
            <material name="black">
              <color rgba="0.12 0.12 0.12 1"/>
            </material>
        </visual>
        <collision>
          <geometry>
            <mesh filename="package://sara_description/meshes/coude.STL" scale="0.001 0.001 0.001"/>
          </geometry>
          <origin xyz="0 0 -0.0005" rpy="3.1416 0 0"/>
        </collision>
        <inertial>
          <mass value="1" />
          <origin xyz="0 0 -0.0005" rpy="3.1416 0 0"/>
          <inertia ixx="0.00124099" ixy="0.0" ixz="0.0"
                   iyy="0.00037378" iyz="0.00026280"
                   izz="0.00135553" />
        </inertial>
      </link>

     <joint name="${prefix}elbow_yaw_joint" type="revolute">
       <parent link="${prefix}forearm_upper_link"/>
       <child link="${prefix}forearm_lower_link"/>
       <limit effort="1000.0" lower="-3.1416" upper="3.1416" velocity="0.5"/>
       <origin xyz="0 0.0945 0" rpy="1.5708 -1.5708 0" />
       <axis xyz="0 0 1" />
     </joint>

     <link name="${prefix}forearm_lower_link">
       <visual>
         <geometry>
           <mesh filename="package://sara_description/meshes/avant_bras.STL" scale="0.001 0.001 0.001"/>
         </geometry>
         <origin xyz="0 0 0" rpy="0 0 0" />
           <material name="black">
             <color rgba="0.12 0.12 0.12 1"/>
           </material>
       </visual>
       <collision>
         <geometry>
           <mesh filename="package://sara_description/meshes/avant_bras.STL" scale="0.001 0.001 0.001"/>
         </geometry>
           <origin xyz="0 0 0" rpy="-1.5708 0 -1.5708" />
       </collision>
       <inertial>
         <mass value="1" />
         <origin xyz="-0.00000184 0.03625492 0.0" rpy="-1.5708 0 -1.5708" />
         <inertia ixx = "0.00007571" ixy = "0.0" ixz = "0.0"
                  iyy = "0.00010905" iyz = "0.0"
                  izz = "0.00011768" />
       </inertial>
     </link>

     <joint name="${prefix}wrist_joint" type="fixed">
       <parent link="${prefix}forearm_lower_link"/>
       <child link="${prefix}wrist_upper_link"/>
       <limit effort="1000.0" lower="-3.1416" upper="3.1416" velocity="0.5"/>
       <origin xyz="0 0 -0.05124" rpy="1.5708 -1.5708 0" />
       <axis xyz="0 1 0" />
     </joint>

     <link name="${prefix}wrist_upper_link">
       <visual>
         <geometry>
           <mesh filename="package://sara_description/meshes/poignet_haut.STL" scale="0.001 0.001 0.001"/>
         </geometry>
         <origin xyz="0 0 0" rpy="0 0 0"/>
         <material name="black">
           <color rgba="0.12 0.12 0.12 1"/>
         </material>
       </visual>
       <collision>
         <geometry>
           <mesh filename="package://sara_description/meshes/poignet_haut.STL" scale="0.001 0.001 0.001"/>
         </geometry>
         <origin xyz="0 0 0" rpy="1.5708 -1.5708 0"/>
       </collision>
       <inertial>
         <mass value="1" />
         <origin xyz="0.00000283 0.03890077 0.00017201" rpy="1.5708 -1.5708 0"/>
         <inertia ixx = "0.00013274" ixy = "0.0" ixz = "0.0"
                  iyy = "0.00007056" iyz = "0.00000150"
                  izz = "0.00011649" />
       </inertial>
     </link>

     <joint name="${prefix}wrist_pitch_joint" type="revolute">
       <parent link="${prefix}wrist_upper_link"/>
       <child link="${prefix}wrist_lower_link"/>
       <limit effort="1000.0" lower="-1.5708" upper="1.5708" velocity="0.5"/>
       <origin xyz="-0.0606 0 0" rpy="1.5708 -1.5708 0" />
       <axis xyz="0 0 1" />
     </joint>

     <link name="${prefix}wrist_lower_link">
       <visual>
         <geometry>
           <mesh filename="package://sara_description/meshes/poignet_bas.STL" scale="0.001 0.001 0.001"/>
         </geometry>
         <origin xyz="0 0 0" rpy=" 0 0 0"/>
         <material name="black">
           <color rgba="0.12 0.12 0.12 1"/>
         </material>
       </visual>
       <collision>
         <geometry>
           <mesh filename="package://sara_description/meshes/poignet_bas.STL" scale="0.001 0.001 0.001"/>
         </geometry>
         <origin xyz="0 0 0" rpy=" 0 1.5708 0"/>
       </collision>
       <inertial>
         <mass value="1" />
         <origin xyz="0.0 0.06377326 -0.000001541" rpy=" 0 1.5708 0"/>
         <inertia ixx = "0.00009654" ixy = "0.0" ixz = "0.0"
                  iyy = "0.00004298" iyz = "0.00000061"
                  izz = "0.00009099" />
       </inertial>
     </link>

     <joint name="${prefix}wrist_roll_joint" type="revolute">
       <parent link="${prefix}wrist_lower_link"/>
       <child link="${prefix}socket_link"/>
       <limit effort="1000.0" lower="-1.49" upper="1.49" velocity="0.5"/>
       <origin xyz="0 0.084375 0" rpy="1.5708 0 0" />
       <axis xyz="1 0 0" />
     </joint>

     <link name="${prefix}socket_link">
       <visual>
         <geometry>
           <mesh filename="package://sara_description/meshes/attache_pince.STL" scale="0.001 0.001 0.001"/>
         </geometry>
         <origin xyz="0 0 0" rpy="0 0 0"/>
         <material name="black">
           <color rgba="0.12 0.12 0.12 1"/>
         </material>
       </visual>
       <collision>
         <geometry>
           <mesh filename="package://sara_description/meshes/attache_pince.STL" scale="0.001 0.001 0.001"/>
         </geometry>
         <origin xyz="0.028925 -0.025 -0.0362070" rpy="0 0 1.5708"/>
       </collision>
       <inertial>
         <mass value="1" />
         <origin xyz="0.0157046 0.0 0.0" rpy="0 0 1.5708"/>
         <inertia ixx = "0.00000933" ixy = "0.0" ixz = "0.0"
                  iyy = "0.00000332" iyz = "0.0"
                  izz = "0.00000955" />
       </inertial>
     </link>

   </xacro:macro>
</robot>
