<?xml version="1.0"?>
<robot xmlns:xacro="http://ros.org/wiki/xacro" >

   <xacro:macro name="sara_arm_v2" params="prefix parent *origin sim">
     <xacro:if value="${sim}">
       <xacro:include filename="$(find sara_description)/urdf/arm_v2/arm.gazebo.xacro" />
       <xacro:sara_arm_gazebo_v2 prefix="${prefix}"/>
     </xacro:if>
     <xacro:include filename="$(find sara_description)/urdf/arm_v2/arm.transmission.xacro" />
     <xacro:sara_arm_transmission_v2 prefix="${prefix}"/>

     <joint name="${prefix}shoulder_roll_joint" type="revolute">
       <parent link="${parent}_link"/>
       <child link="${prefix}clavicular_link"/>
       <dynamics damping="0.1"/>
       <limit effort="10000.0" lower="-1.6" upper="1.4" velocity="0.5"/>
       <xacro:insert_block name="origin"/>
       <axis xyz="0 0 1" />
     </joint>

     <link name="${prefix}clavicular_link">
       <visual>
         <geometry>
           <mesh filename="package://sara_description/meshes/epaule1.STL" scale="0.001 0.001 0.001"/>
         </geometry>
         <origin xyz="0 0 0" rpy="0 0 0"/>
         <material name="black">
           <color rgba="0.12 0.12 0.12 1"/>
         </material>
       </visual>
       <collision>
         <geometry>
           <mesh filename="package://sara_description/meshes/epaule1.STL" scale="0.001 0.001 0.001"/>
         </geometry>
           <origin xyz="0 0 0" rpy="0 0 0"/>
       </collision>
       <inertial>
         <mass value="0.28506911" />
         <origin xyz="0.0 -0.03225261 -0.01842117" rpy="0 0 0" />
         <inertia ixx = "0.00040678" ixy="0.0" ixz = "-0.00000004"
                  iyy = "0.00039958" iyz = "-0.00003453"
                  izz = "0.00059825" />
       </inertial>
     </link>

     <joint name="${prefix}shoulder_pitch_joint" type="revolute">
       <parent link="${prefix}clavicular_link"/>
       <child link="${prefix}upper_arm_upper_link"/>
       <dynamics damping="0.1"/>
       <limit effort="10000.0" lower="-4.7124" upper="1.5708" velocity="0.5"/>
       <origin xyz="0 -0.085 0" rpy="-1.57 0 0" />
       <axis xyz="0 0 1" />
     </joint>

     <link name="${prefix}upper_arm_upper_link">
       <visual>
         <geometry>
           <mesh filename="package://sara_description/meshes/epaule2.STL" scale="0.001 0.001 0.001"/>
         </geometry>
           <origin xyz="0 0 0" rpy="0 0 0"/>
           <material name="black">
             <color rgba="0.12 0.12 0.12 1"/>
           </material>
       </visual>
       <collision>
         <geometry>
           <mesh filename="package://sara_description/meshes/epaule2.STL" scale="0.001 0.001 0.001"/>
         </geometry>
           <origin xyz="0 0 0" rpy="0 0 0"/>
         </collision>
         <inertial>
           <mass value="0.28506911" />
           <origin xyz="-0.03225261 0 -0.01842117" rpy="0 0 0"/>
           <inertia ixx = "0.00039958" ixy="0" ixz = "-0.00003453" iyy = "0.00040678" iyz = "0.00000004" izz = "0.00059825" />
         </inertial>
     </link>

     <joint name="${prefix}shoulder_yaw_joint" type="revolute">
       <parent link="${prefix}upper_arm_upper_link"/>
       <child link="${prefix}upper_arm_lower_link"/>
       <dynamics damping="0.1"/>
       <limit effort="10000.0" lower="-3.1416" upper="3.1416" velocity="0.5"/>
       <origin xyz="-0.085 0 0" rpy="1.5708 0 1.5708" />
       <axis xyz="0 0 1" />
     </joint>

     <link name="${prefix}upper_arm_lower_link">
       <visual>
         <geometry>
           <mesh filename="package://sara_description/meshes/bras_haut.STL" scale="0.001 0.001 0.001"/>
         </geometry>
         <origin xyz="0 0 0" rpy="0 0 0"/>
         <material name="black">
           <color rgba="0.12 0.12 0.12 1"/>
         </material>
       </visual>
       <collision>
         <geometry>
           <mesh filename="package://sara_description/meshes/bras_haut.STL" scale="0.001 0.001 0.001"/>
         </geometry>
         <origin xyz="0 0 0" rpy="0 0 0"/>
       </collision>
       <inertial>
         <mass value="0.85240803" />
         <origin xyz="-0.00168302 0.00155140 -0.13913505" rpy="0 0 0"/>
         <inertia ixx = "0.00538199" ixy = "-0.00000635" ixz = "0.00012863"
                  iyy = "0.00562525" iyz = "-0.00012986"
                  izz = "0.00050159" />
       </inertial>
     </link>

      <joint name="${prefix}elbow_pitch_joint" type="revolute">
        <parent link="${prefix}upper_arm_lower_link"/>
        <child link="${prefix}forearm_upper_link"/>
        <dynamics damping="0.1"/>
        <limit effort="10000.0" lower="-2.20" upper="1.90" velocity="0.5"/>
        <origin xyz="0 0 -0.31" rpy="-1.5708 0 0" />
        <axis xyz="0 0 1" />
      </joint>

      <link name="${prefix}forearm_upper_link">
        <visual>
          <geometry>
            <mesh filename="package://sara_description/meshes/coude.STL" scale="0.001 0.001 0.001"/>
          </geometry>
            <origin xyz="0 0 -0.0005" rpy="0 0 0"/>
            <material name="black">
              <color rgba="0.12 0.12 0.12 1"/>
            </material>
        </visual>
        <collision>
          <geometry>
            <mesh filename="package://sara_description/meshes/coude.STL" scale="0.001 0.001 0.001"/>
          </geometry>
          <origin xyz="0 0 0" rpy="0 0 0"/>
        </collision>
        <inertial>
          <mass value="0.28300045" />
          <origin xyz="0.00000207 0.03922132 -0.01628605" rpy="0 0 0"/>
          <inertia ixx = "0.00036109" ixy = "0.0" ixz = "-0.00000002"
                   iyy = "0.00029872" iyz = "0.00001701"
                   izz = "0.00055069" />
        </inertial>
      </link>

     <joint name="${prefix}elbow_yaw_joint" type="revolute">
       <parent link="${prefix}forearm_upper_link"/>
       <child link="${prefix}forearm_lower_link"/>
       <dynamics damping="0.1"/>
       <limit effort="10000.0" lower="-3.1416" upper="3.1416" velocity="0.5"/>
       <origin xyz="0 0.0945 0" rpy="1.5708 -1.5708 0" />
       <axis xyz="0 0 1" />
     </joint>

     <link name="${prefix}forearm_lower_link">
       <visual>
         <geometry>
           <mesh filename="package://sara_description/meshes/avant_bras.STL" scale="0.001 0.001 0.001"/>
         </geometry>
         <origin xyz="0 0 0" rpy="0 0 0" />
           <material name="black">
             <color rgba="0.12 0.12 0.12 1"/>
           </material>
       </visual>
       <collision>
         <geometry>
           <mesh filename="package://sara_description/meshes/avant_bras.STL" scale="0.001 0.001 0.001"/>
         </geometry>
           <origin xyz="0 0 0" rpy="0 0 0"/>
       </collision>
       <inertial>
         <mass value="0.1177" />
         <origin xyz="0.0 -0.00000184 -0.03625492" rpy="0 0 0" />
         <inertia ixx = "0.54274952" ixy = "0.0" ixz = "0.0"
                  iyy = "1.03078569" iyz = "0.0"
                  izz = "0.00010905" />
       </inertial>
     </link>

     <joint name="${prefix}wrist_joint" type="fixed">
       <parent link="${prefix}forearm_lower_link"/>
       <child link="${prefix}wrist_upper_link"/>
       <limit effort="10000.0" lower="-3.1416" upper="3.1416" velocity="0.5"/>
       <origin xyz="0 0 -0.05124" rpy="1.5708 -1.5708 0" />
       <axis xyz="0 1 0" />
     </joint>

     <link name="${prefix}wrist_upper_link">
       <visual>
         <geometry>
           <mesh filename="package://sara_description/meshes/poignet_haut.STL" scale="0.001 0.001 0.001"/>
         </geometry>
         <origin xyz="0 0 0" rpy="0 0 0"/>
         <material name="black">
           <color rgba="0.12 0.12 0.12 1"/>
         </material>
       </visual>
       <collision>
         <geometry>
           <mesh filename="package://sara_description/meshes/poignet_haut.STL" scale="0.001 0.001 0.001"/>
         </geometry>
         <origin xyz="0 0 0" rpy="0 0 0"/>
       </collision>
       <inertial>
         <mass value="0.1956991" />
         <origin xyz="-0.03893593 0.00017228 -0.00000284" rpy="0 0 0"/>
         <inertia ixx = "0.00007035" ixy = "-0.00000150" ixz = "0.0"
                  iyy = "0.00011510" iyz = "0.0"
                  izz = "0.00013235" />
       </inertial>
     </link>

     <joint name="${prefix}wrist_pitch_joint" type="revolute">
       <parent link="${prefix}wrist_upper_link"/>
       <child link="${prefix}wrist_lower_link"/>
       <dynamics damping="0.1"/>
       <limit effort="10000.0" lower="-1.5708" upper="1.5708" velocity="0.5"/>
       <origin xyz="-0.0606 0 0" rpy="1.5708 -1.5708 0" />
       <axis xyz="0 0 1" />
     </joint>

     <link name="${prefix}wrist_lower_link">
       <visual>
         <geometry>
           <mesh filename="package://sara_description/meshes/poignet_bas.STL" scale="0.001 0.001 0.001"/>
         </geometry>
         <origin xyz="0 0 0" rpy=" 0 0 0"/>
         <material name="black">
           <color rgba="0.12 0.12 0.12 1"/>
         </material>
       </visual>
       <collision>
         <geometry>
           <mesh filename="package://sara_description/meshes/poignet_bas.STL" scale="0.001 0.001 0.001"/>
         </geometry>
         <origin xyz="0 0 0" rpy="0 0 0"/>
       </collision>
       <inertial>
         <mass value="0.18747684" />
         <origin xyz="0.00001243 0.05721169 0.0" rpy=" 0 0 0"/>
         <inertia ixx = "0.00015391" ixy = "-0.00000060" ixz = "0.0"
                  iyy = "0.00006260" iyz = "0.0"
                  izz = "0.00015218" />
       </inertial>
     </link>

     <joint name="${prefix}wrist_roll_joint" type="revolute">
       <parent link="${prefix}wrist_lower_link"/>
       <child link="${prefix}socket_link"/>
       <dynamics damping="0.1"/>
       <limit effort="10000.0" lower="-1.49" upper="1.49" velocity="0.5"/>
       <origin xyz="0 0.084375 0" rpy="1.5708 0 0" />
       <axis xyz="1 0 0" />
     </joint>

     <link name="${prefix}socket_link">
       <visual>
         <geometry>
           <mesh filename="package://sara_description/meshes/attache_pince.STL" scale="0.001 0.001 0.001"/>
         </geometry>
         <origin xyz="0 0 0" rpy="0 0 0"/>
         <material name="black">
           <color rgba="0.12 0.12 0.12 1"/>
         </material>
       </visual>
       <collision>
         <geometry>
           <mesh filename="package://sara_description/meshes/attache_pince.STL" scale="0.001 0.001 0.001"/>
         </geometry>
         <origin xyz="0 0 0" rpy="0 0 0"/>
       </collision>
       <inertial>
         <mass value="0.02796" />
         <origin xyz="0.0 0.0 -0.01570460" rpy="0 0 0"/>
         <inertia ixx = "0.00000889" ixy = "0.0" ixz = "0.0"
                  iyy= "0.00002569" iyz = "0.0"
                  izz = "0.00002493" />
       </inertial>
     </link>

     <joint name="${prefix}gripper_joint" type="fixed">
       <parent link="${prefix}socket_link"/>
       <child link="${prefix}robotiq_arg2f_base_link"/>
       <dynamics damping="0.1"/>
       <limit effort="10000.0" lower="-1.49" upper="1.49" velocity="0.5"/>
       <origin xyz="0 0 0" rpy="0 0 0" />
        <axis xyz="0 1 0" />
     </joint>



   </xacro:macro>
</robot>
