<?xml version="1.0" ?>
<!-- =================================================================================== -->
<!-- |    This document was autogenerated by xacro from sara.urdf.xacro                | -->
<!-- |    EDITING THIS FILE BY HAND IS NOT RECOMMENDED                                 | -->
<!-- =================================================================================== -->
<robot name="sara" xmlns:xacro="http://ros.org/wiki/xacro">
  <gazebo>
    <plugin filename="libgazebo_ros_control.so" name="gazebo_ros_control">
      <robotNamespace>/</robotNamespace>
    </plugin>
  </gazebo>
  <gazebo reference="base_link">
    <turnGravityOff>false</turnGravityOff>
    <selfCollide>true</selfCollide>
  </gazebo>
  <gazebo>
    <plugin filename="libgazebo_ros_planar_move.so" name="object_controller">
      <commandTopic>/cmd_vel</commandTopic>
      <odometryTopic>/odom</odometryTopic>
      <odometryFrame>odom</odometryFrame>
      <odometryRate>20.0</odometryRate>
      <robotBaseFrame>base_link</robotBaseFrame>
    </plugin>
  </gazebo>
  <link name="base_link">
    <visual>
      <geometry>
        <mesh filename="package://sara_description/meshes/base.STL" scale="0.001 0.001 0.001"/>
      </geometry>
      <origin rpy="-1.57 0 1.57" xyz="0.295 -0.250 0.85635"/>
      <material name="black">
        <color rgba="0.12 0.12 0.12 1"/>
      </material>
    </visual>
    <visual>
      <geometry>
        <box size="0.4 0.35635 0.454"/>
      </geometry>
      <origin rpy="0 0 0" xyz="-0.055 0 0.227"/>
      <material name="black">
        <color rgba="0.12 0.12 0.12 1"/>
      </material>
    </visual>
    <collision>
      <geometry>
        <mesh filename="package://sara_description/meshes/base.STL" scale="0.001 0.001 0.001"/>
      </geometry>
      <origin rpy="-1.57 0 1.57" xyz="0.295 -0.250 0.85635"/>
    </collision>
    <collision>
      <geometry>
        <box size="0.4 0.35635 0.454"/>
      </geometry>
      <origin rpy="0 0 0" xyz="-0.055 0 0.227"/>
    </collision>
    <inertial>
      <mass value="100"/>
      <origin rpy="0 0 0" xyz="-0.055 0 0.227"/>
      <inertia ixx="0.1" ixy="0.1" ixz="0.1" iyy="0.1" iyz="0.1" izz="0.1"/>
    </inertial>
    <inertial>
      <mass value="30"/>
      <origin rpy="0 0 0" xyz="0 0 0"/>
      <inertia ixx="0.1" ixy="0.1" ixz="0.1" iyy="0.1" iyz="0.1" izz="0.1"/>
    </inertial>
  </link>
  <!-- hokuyo -->
  <gazebo reference="front_hokuyo_link">
    <turnGravityOff>false</turnGravityOff>
    <sensor name="front_hokuyo_sensor" type="ray">
      <pose>0 0 0 0 0 0.0425</pose>
      <visualize>true</visualize>
      <update_rate>30</update_rate>
      <ray>
        <scan>
          <horizontal>
            <samples>720</samples>
            <resolution>1</resolution>
            <min_angle>-1.57</min_angle>
            <max_angle>1.57</max_angle>
          </horizontal>
        </scan>
        <range>
          <min>0.10</min>
          <max>30.0</max>
          <resolution>0.01</resolution>
        </range>
        <noise>
          <type>gaussian</type>
          <!-- Noise parameters based on published spec for Hokuyo laser
                                            achieving "+-30mm" accuracy at range < 10m.  A mean of 0.0m and
                                            stddev of 0.01m will put 99.7% of samples within 0.03m of the true
                                            reading. -->
          <mean>0.0</mean>
          <stddev>0.01</stddev>
        </noise>
      </ray>
      <plugin filename="libgazebo_ros_laser.so" name="gazebo_ros_front__hokuyo_controller">
        <topicName>/hokuo/scan</topicName>
        <frameName>hokuyo_link</frameName>
      </plugin>
    </sensor>
  </gazebo>
  <joint name="front_hokuyo_joint" type="fixed">
    <parent link="base_link"/>
    <child link="front_hokuyo_link"/>
    <origin rpy="0 0 0" xyz="0.2516879 0 0"/>
  </joint>
  <link name="front_hokuyo_link">
    <visual>
      <geometry>
        <cylinder length="0.085" radius="0.03"/>
      </geometry>
      <origin rpy="0 0 0" xyz="0 0 0"/>
      <material name="orange">
        <color rgba="1 0.5 0 1"/>
      </material>
    </visual>
    <collision>
      <geometry>
        <cylinder length="0.085" radius="0.03"/>
      </geometry>
      <origin rpy="0 0 0" xyz="0 0 0"/>
    </collision>
    <inertial>
      <mass value="0.5"/>
      <origin rpy="0 0 0" xyz="0 0 0"/>
      <inertia ixx="0.001" ixy="0" ixz="0" iyy="0.001" iyz="0" izz="0.001"/>
    </inertial>
  </link>
  <gazebo reference="front_left_mecanum_wheel_link">
    <mu1 value="0"/>
    <mu2 value="0"/>
    <kp value="0"/>
    <kd value="0"/>
    <fdir1 value="1 0 0"/>
    <material>Gazebo/Orange</material>
    <turnGravityOff>false</turnGravityOff>
  </gazebo>
  <!--<xacro:macanum_wheel_transmission position="${position}"/>-->
  <link name="front_left_mecanum_wheel_link"/>
  <joint name="front_left_mecanum_wheel_joint" type="continuous">
    <parent link="base_link"/>
    <child link="front_left_mecanum_wheel_link"/>
    <axis xyz="0 0 1"/>
    <origin rpy=" -1.57079632679 0 0" xyz="0.205631 0.22735 -0.06"/>
  </joint>
  <gazebo reference="front_right_mecanum_wheel_link">
    <mu1 value="0"/>
    <mu2 value="0"/>
    <kp value="0"/>
    <kd value="0"/>
    <fdir1 value="1 0 0"/>
    <material>Gazebo/Orange</material>
    <turnGravityOff>false</turnGravityOff>
  </gazebo>
  <!--<xacro:macanum_wheel_transmission position="${position}"/>-->
  <link name="front_right_mecanum_wheel_link"/>
  <joint name="front_right_mecanum_wheel_joint" type="continuous">
    <parent link="base_link"/>
    <child link="front_right_mecanum_wheel_link"/>
    <axis xyz="0 0 1"/>
    <origin rpy=" 1.57079632679 0 0" xyz="0.205631 -0.22735 -0.06"/>
  </joint>
  <gazebo reference="rear_left_mecanum_wheel_link">
    <mu1 value="0"/>
    <mu2 value="0"/>
    <kp value="0"/>
    <kd value="0"/>
    <fdir1 value="1 0 0"/>
    <material>Gazebo/Orange</material>
    <turnGravityOff>false</turnGravityOff>
  </gazebo>
  <!--<xacro:macanum_wheel_transmission position="${position}"/>-->
  <link name="rear_left_mecanum_wheel_link"/>
  <joint name="rear_left_mecanum_wheel_joint" type="continuous">
    <parent link="base_link"/>
    <child link="rear_left_mecanum_wheel_link"/>
    <axis xyz="0 0 1"/>
    <origin rpy=" -1.57079632679 0 0" xyz="-0.205631 0.22735 -0.06"/>
  </joint>
  <gazebo reference="rear_right_mecanum_wheel_link">
    <mu1 value="0"/>
    <mu2 value="0"/>
    <kp value="0"/>
    <kd value="0"/>
    <fdir1 value="1 0 0"/>
    <material>Gazebo/Orange</material>
    <turnGravityOff>false</turnGravityOff>
  </gazebo>
  <!--<xacro:macanum_wheel_transmission position="${position}"/>-->
  <link name="rear_right_mecanum_wheel_link"/>
  <joint name="rear_right_mecanum_wheel_joint" type="continuous">
    <parent link="base_link"/>
    <child link="rear_right_mecanum_wheel_link"/>
    <axis xyz="0 0 1"/>
    <origin rpy=" 1.57079632679 0 0" xyz="-0.205631 -0.22735 -0.06"/>
  </joint>
  <gazebo reference="torso_link">
    <turnGravityOff>false</turnGravityOff>
    <selfCollide>true</selfCollide>
  </gazebo>
  <joint name="base_torso_joint" type="fixed">
    <parent link="base_link"/>
    <child link="torso_link"/>
    <limit effort="1000.0" lower="0" upper="0.5" velocity="0.2"/>
    <origin rpy="0 0 0" xyz="0.177374 0 0.70531"/>
    <axis xyz="0 0 1"/>
  </joint>
  <link name="torso_link">
    <visual>
      <geometry>
        <mesh filename="package://sara_description/meshes/torse.STL" scale="0.001 0.001 0.001"/>
      </geometry>
      <origin rpy="1.5708 0 1.5708" xyz="-0.14427 -0.197233 0"/>
      <material name="black">
        <color rgba="0.12 0.12 0.12 1"/>
      </material>
    </visual>
    <collision>
      <geometry>
        <mesh filename="package://sara_description/meshes/torse.STL" scale="0.001 0.001 0.001"/>
      </geometry>
      <origin rpy="1.5708 0 1.5708" xyz="-0.14427 -0.197233 0"/>
    </collision>
    <inertial>
      <mass value="10"/>
      <origin rpy="1.5708 0 1.5708" xyz="-0.14427 -0.197233 0"/>
      <inertia ixx="0.001" ixy="0" ixz="0" iyy="0.001" iyz="0" izz="0.001"/>
    </inertial>
  </link>
  <gazebo reference="kinect2_link">
    <turnGravityOff>false</turnGravityOff>
    <selfCollide>true</selfCollide>
  </gazebo>
  <joint name="base_kinect2_joint" type="fixed">
    <parent link="base_link"/>
    <child link="kinect2_link"/>
    <limit effort="1000.0" lower="0" upper="0.5" velocity="0.2"/>
    <origin rpy="-1.5708 0 -1.5708" xyz="0.177374 0 0.65676"/>
    <axis xyz="0 0 1"/>
  </joint>
  <link name="kinect2_link">
    <visual>
      <geometry>
        <mesh filename="package://sara_description/meshes/kinect.STL" scale="0.001 0.001 0.001"/>
      </geometry>
      <origin rpy="1.5708 0 0" xyz="-0.13466 0 -0.028975"/>
      <material name="black">
        <color rgba="0.12 0.12 0.12 1"/>
      </material>
    </visual>
    <collision>
      <geometry>
        <mesh filename="package://sara_description/meshes/kinect.STL" scale="0.001 0.001 0.001"/>
      </geometry>
      <origin rpy="1.5708 0 0" xyz="-0.13466 0 -0.028975"/>
    </collision>
    <inertial>
      <mass value="10"/>
      <origin rpy="1.5708 0 0" xyz="-0.13466 0 -0.028975"/>
      <inertia ixx="0.001" ixy="0" ixz="0" iyy="0.001" iyz="0" izz="0.001"/>
    </inertial>
  </link>
  <gazebo reference="neck_link">
    <turnGravityOff>false</turnGravityOff>
    <selfCollide>true</selfCollide>
  </gazebo>
  <transmission name="head_yaw_trans" type="SimpleTransmission">
    <type>transmission_interface/SimpleTransmission</type>
    <actuator name="head_yaw_motor">
      <mechanicalReduction>1</mechanicalReduction>
    </actuator>
    <joint name="head_yaw_joint">
      <hardwareInterface>PositionJointInterface</hardwareInterface>
    </joint>
  </transmission>
  <joint name="head_yaw_joint" type="revolute">
    <parent link="torso_link"/>
    <child link="neck_link"/>
    <limit effort="1000.0" lower="-1.22173" upper="1.22173" velocity="0.5"/>
    <origin rpy="0 0 0" xyz="0.032295 0 0.2777"/>
    <axis xyz="0 0 1"/>
  </joint>
  <link name="neck_link">
    <visual>
      <geometry>
        <mesh filename="package://sara_description/meshes/cou.STL" scale="0.001 0.001 0.001"/>
      </geometry>
      <origin rpy="1.5708 0 1.5708" xyz="0 0 0"/>
      <material name="blue">
        <color rgba="0.06 0.06 1 1"/>
      </material>
    </visual>
    <collision>
      <geometry>
        <mesh filename="package://sara_description/meshes/cou.STL" scale="0.001 0.001 0.001"/>
      </geometry>
      <origin rpy="1.5708 0 1.5708" xyz="0 0 0"/>
    </collision>
    <inertial>
      <mass value="2"/>
      <origin rpy="1.5708 0 1.5708" xyz="0 0 0"/>
      <inertia ixx="0.001" ixy="0" ixz="0" iyy="0.001" iyz="0" izz="0.001"/>
    </inertial>
  </link>
  <gazebo reference="head_link">
    <turnGravityOff>false</turnGravityOff>
    <selfCollide>true</selfCollide>
  </gazebo>
  <transmission name="head_pitch_trans" type="SimpleTransmission">
    <type>transmission_interface/SimpleTransmission</type>
    <actuator name="head_pitch_motor">
      <mechanicalReduction>1</mechanicalReduction>
    </actuator>
    <joint name="head_pitch_joint">
      <hardwareInterface>PositionJointInterface</hardwareInterface>
    </joint>
  </transmission>
  <joint name="head_pitch_joint" type="revolute">
    <parent link="neck_link"/>
    <child link="head_link"/>
    <limit effort="1000.0" lower="-0.40" upper="1.04" velocity="0.5"/>
    <origin rpy="-1.57 0 0" xyz="0 0 0.0927"/>
    <axis xyz="0 0 1"/>
  </joint>
  <link name="head_link">
    <visual>
      <geometry>
        <mesh filename="package://sara_description/meshes/tete.STL" scale="0.001 0.001 0.001"/>
      </geometry>
      <origin rpy="1.5708 -1.5708 1.5708" xyz="0 0 0"/>
      <material name="blue">
        <color rgba="0.06 0.06 1 1"/>
      </material>
    </visual>
    <collision>
      <geometry>
        <mesh filename="package://sara_description/meshes/tete.STL" scale="0.001 0.001 0.001"/>
      </geometry>
      <origin rpy="1.5708 -1.5708 1.5708" xyz="0 0 0"/>
    </collision>
    <inertial>
      <mass value="5"/>
      <origin rpy="1.5708 0 1.5708" xyz="0 0 0"/>
      <inertia ixx="0.001" ixy="0" ixz="0" iyy="0.001" iyz="0" izz="0.001"/>
    </inertial>
  </link>
  <joint name="head_xtion_depth_joint" type="fixed">
    <origin rpy="0 0 0" xyz="0.0 0.049 0.0"/>
    <parent link="head_xtion_link"/>
    <child link="head_xtion_depth_frame"/>
  </joint>
  <link name="head_xtion_depth_frame"/>
  <joint name="head_xtion_depth_optical_joint" type="fixed">
    <origin rpy="-1.57079632679 0.0 -1.57079632679" xyz="0 0 0"/>
    <parent link="head_xtion_depth_frame"/>
    <child link="head_xtion_depth_optical_frame"/>
  </joint>
  <link name="head_xtion_depth_optical_frame"/>
  <joint name="head_xtion_rgb_joint" type="fixed">
    <origin rpy="0 0 0" xyz="0.0 0.022 0.0"/>
    <parent link="head_xtion_link"/>
    <child link="head_xtion_rgb_frame"/>
  </joint>
  <link name="head_xtion_rgb_frame"/>
  <joint name="head_xtion_rgb_optical_joint" type="fixed">
    <origin rpy="-1.57079632679 0.0 -1.57079632679" xyz="0 0 0"/>
    <parent link="head_xtion_rgb_frame"/>
    <child link="head_xtion_rgb_optical_frame"/>
  </joint>
  <link name="head_xtion_rgb_optical_frame"/>
  <!-- ASUS Xtion PRO camera for simulation -->
  <gazebo reference="head_xtion_depth_frame">
    <sensor name="head_xtion" type="depth">
      <update_rate>20</update_rate>
      <camera>
        <horizontal_fov>1.09606677025</horizontal_fov>
        <image>
          <format>R8G8B8</format>
          <width>640</width>
          <height>480</height>
        </image>
        <clip>
          <near>0.5</near>
          <far>9</far>
        </clip>
      </camera>
      <plugin filename="libgazebo_ros_openni_kinect.so" name="head_xtion_camera_controller">
        <alwaysOn>true</alwaysOn>
        <updateRate>20</updateRate>
        <imageTopicName>head_xtion/rgb/image_raw</imageTopicName>
        <cameraInfoTopicName>head_xtion/rgb/camera_info</cameraInfoTopicName>
        <depthImageTopicName>head_xtion/depth/image_raw</depthImageTopicName>
        <depthImageCameraInfoTopicName>head_xtion/depth/camera_info</depthImageCameraInfoTopicName>
        <pointCloudTopicName>head_xtion/depth/points</pointCloudTopicName>
        <frameName>head_xtion_depth_optical_frame</frameName>
        <distortion_k1>0.0</distortion_k1>
        <distortion_k2>0.0</distortion_k2>
        <distortion_k3>0.0</distortion_k3>
        <distortion_t1>0.0</distortion_t1>
        <distortion_t2>0.0</distortion_t2>
      </plugin>
    </sensor>
  </gazebo>
  <joint name="head_xtion_joint" type="fixed">
    <origin rpy="1.57 0 0" xyz="0.0776104 -0.13 0"/>
    <parent link="head_link"/>
    <child link="head_xtion_link"/>
  </joint>
  <link name="head_xtion_link">
    <inertial>
      <mass value="0.200"/>
      <origin rpy="1.5708 0 1.5708" xyz="0 0 0"/>
      <inertia ixx="5.8083e-4" ixy="0" ixz="0" iyy="3.0833e-5" iyz="0" izz="5.9083e-4"/>
    </inertial>
    <visual>
      <origin rpy="1.5708 0 1.5708" xyz="0 0 0"/>
      <geometry>
        <mesh filename="package://sara_description/meshes/xtion.STL" scale="0.001 0.001 0.001"/>
      </geometry>
    </visual>
    <collision>
      <origin rpy="1.5708 0 1.5708" xyz="0 0 0"/>
      <geometry>
        <box size="0.035 0.185 0.025"/>
      </geometry>
    </collision>
  </link>
  <gazebo reference="right_clavicular_link">
    <turnGravityOff>false</turnGravityOff>
    <selfCollide>true</selfCollide>
  </gazebo>
  <gazebo reference="right_upper_arm_upper_link">
    <turnGravityOff>false</turnGravityOff>
    <selfCollide>true</selfCollide>
  </gazebo>
  <gazebo reference="right_upper_arm_lower_link">
    <turnGravityOff>false</turnGravityOff>
    <selfCollide>true</selfCollide>
  </gazebo>
  <gazebo reference="right_forearm_upper_link">
    <turnGravityOff>false</turnGravityOff>
    <selfCollide>true</selfCollide>
  </gazebo>
  <gazebo reference="right_forearm_lower_link">
    <turnGravityOff>false</turnGravityOff>
    <selfCollide>true</selfCollide>
  </gazebo>
  <gazebo reference="right_upper_wrist_link">
    <turnGravityOff>false</turnGravityOff>
    <selfCollide>true</selfCollide>
  </gazebo>
  <gazebo reference="right_lower_wrist_link">
    <turnGravityOff>false</turnGravityOff>
    <selfCollide>true</selfCollide>
  </gazebo>
  <gazebo reference="right_socket_link">
    <turnGravityOff>false</turnGravityOff>
    <selfCollide>true</selfCollide>
  </gazebo>
  <transmission name="right_shoulder_roll_trans" type="SimpleTransmission">
    <type>transmission_interface/SimpleTransmission</type>
    <actuator name="right_shoulder_roll_motor">
      <mechanicalReduction>1</mechanicalReduction>
    </actuator>
    <joint name="right_shoulder_roll_joint">
      <hardwareInterface>VelocityJointInterface</hardwareInterface>
    </joint>
  </transmission>
  <transmission name="right_shoulder_pitch_trans" type="SimpleTransmission">
    <type>transmission_interface/SimpleTransmission</type>
    <actuator name="right_shoulder_pitch_motor">
      <mechanicalReduction>1</mechanicalReduction>
    </actuator>
    <joint name="right_shoulder_pitch_joint">
      <hardwareInterface>VelocityJointInterface</hardwareInterface>
    </joint>
  </transmission>
  <transmission name="right_shoulder_yaw_trans" type="SimpleTransmission">
    <type>transmission_interface/SimpleTransmission</type>
    <actuator name="right_shoulder_yaw_motor">
      <mechanicalReduction>1</mechanicalReduction>
    </actuator>
    <joint name="right_shoulder_yaw_joint">
      <hardwareInterface>VelocityJointInterface</hardwareInterface>
    </joint>
  </transmission>
  <transmission name="right_elbow_pitch_trans" type="SimpleTransmission">
    <type>transmission_interface/SimpleTransmission</type>
    <actuator name="right_elbow_pitch_motor">
      <mechanicalReduction>1</mechanicalReduction>
    </actuator>
    <joint name="right_elbow_pitch_joint">
      <hardwareInterface>VelocityJointInterface</hardwareInterface>
    </joint>
  </transmission>
  <transmission name="right_elbow_yaw_trans" type="SimpleTransmission">
    <type>transmission_interface/SimpleTransmission</type>
    <actuator name="right_elbow_yaw_motor">
      <mechanicalReduction>1</mechanicalReduction>
    </actuator>
    <joint name="right_elbow_yaw_joint">
      <hardwareInterface>VelocityJointInterface</hardwareInterface>
    </joint>
  </transmission>
  <transmission name="right_wrist_pitch_trans" type="SimpleTransmission">
    <type>transmission_interface/SimpleTransmission</type>
    <actuator name="right_wrist_pitch_motor">
      <mechanicalReduction>1</mechanicalReduction>
    </actuator>
    <joint name="right_wrist_pitch_joint">
      <hardwareInterface>VelocityJointInterface</hardwareInterface>
    </joint>
  </transmission>
  <transmission name="right_wrist_yaw_trans" type="SimpleTransmission">
    <type>transmission_interface/SimpleTransmission</type>
    <actuator name="right_wrist_yaw_motor">
      <mechanicalReduction>1</mechanicalReduction>
    </actuator>
    <joint name="right_wrist_yaw_joint">
      <hardwareInterface>VelocityJointInterface</hardwareInterface>
    </joint>
  </transmission>
  <joint name="right_shoulder_roll_joint" type="revolute">
    <parent link="torso_link"/>
    <child link="right_clavicular_link"/>
    <limit effort="1000.0" lower="-1.6" upper="1.4" velocity="0.5"/>
    <origin rpy="0 -1.57 0" xyz="0 -0.145 0.189"/>
    <axis xyz="0 0 1"/>
  </joint>
  <link name="right_clavicular_link">
    <visual>
      <geometry>
        <mesh filename="package://sara_description/meshes/epaule.STL" scale="0.001 0.001 0.001"/>
      </geometry>
      <origin rpy="0 3.1416 0" xyz="0 0 0"/>
      <material name="black">
        <color rgba="0.12 0.12 0.12 1"/>
      </material>
    </visual>
    <collision>
      <geometry>
        <mesh filename="package://sara_description/meshes/epaule.STL" scale="0.001 0.001 0.001"/>
      </geometry>
      <origin rpy="0 3.1416 0" xyz="0 0 0"/>
    </collision>
    <inertial>
      <mass value="1"/>
      <origin rpy="0 3.1416 0" xyz="0 0 0"/>
      <inertia ixx="0.001" ixy="0" ixz="0" iyy="0.001" iyz="0" izz="0.001"/>
    </inertial>
  </link>
  <joint name="right_shoulder_pitch_joint" type="revolute">
    <parent link="right_clavicular_link"/>
    <child link="right_upper_arm_upper_link"/>
    <limit effort="1000.0" lower="-4.7124" upper="1.5708" velocity="0.5"/>
    <origin rpy="-1.57 0 0" xyz="0 -0.085 0"/>
    <axis xyz="0 0 1"/>
  </joint>
  <link name="right_upper_arm_upper_link">
    <visual>
      <geometry>
        <mesh filename="package://sara_description/meshes/epaule.STL" scale="0.001 0.001 0.001"/>
      </geometry>
      <origin rpy="3.1416 0 1.5708" xyz="0 0 0"/>
      <material name="black">
        <color rgba="0.12 0.12 0.12 1"/>
      </material>
    </visual>
    <collision>
      <geometry>
        <mesh filename="package://sara_description/meshes/epaule.STL" scale="0.001 0.001 0.001"/>
      </geometry>
      <origin rpy="3.1416 0 1.5708" xyz="0 0 0"/>
    </collision>
    <inertial>
      <mass value="1"/>
      <origin rpy="3.1416 0 1.5708" xyz="0 0 0"/>
      <inertia ixx="0.001" ixy="0" ixz="0" iyy="0.001" iyz="0" izz="0.001"/>
    </inertial>
  </link>
  <joint name="right_shoulder_yaw_joint" type="revolute">
    <parent link="right_upper_arm_upper_link"/>
    <child link="right_upper_arm_lower_link"/>
    <limit effort="1000.0" lower="-3.1416" upper="3.1416" velocity="0.5"/>
    <origin rpy="1.5708 0 1.5708" xyz="-0.085 0 0"/>
    <axis xyz="0 0 1"/>
  </joint>
  <link name="right_upper_arm_lower_link">
    <visual>
      <geometry>
        <mesh filename="package://sara_description/meshes/bras_haut.STL" scale="0.001 0.001 0.001"/>
      </geometry>
      <origin rpy="1.5708 3.1416 3.1416" xyz="0 0 0"/>
      <material name="black">
        <color rgba="0.12 0.12 0.12 1"/>
      </material>
    </visual>
    <collision>
      <geometry>
        <mesh filename="package://sara_description/meshes/bras_haut.STL" scale="0.001 0.001 0.001"/>
      </geometry>
      <origin rpy="1.5708 3.1416 3.1416" xyz="0 0 0"/>
    </collision>
    <inertial>
      <mass value="1"/>
      <origin rpy="1.5708 3.1416 3.1416" xyz="0 0 0"/>
      <inertia ixx="0.001" ixy="0" ixz="0" iyy="0.001" iyz="0" izz="0.001"/>
    </inertial>
  </link>
  <joint name="right_elbow_pitch_joint" type="revolute">
    <parent link="right_upper_arm_lower_link"/>
    <child link="right_forearm_upper_link"/>
    <limit effort="1000.0" lower="-2.20" upper="1.90" velocity="0.5"/>
    <origin rpy="-1.5708 0 0" xyz="0 0 -0.31"/>
    <axis xyz="0 0 1"/>
  </joint>
  <link name="right_forearm_upper_link">
    <visual>
      <geometry>
        <mesh filename="package://sara_description/meshes/coude.STL" scale="0.001 0.001 0.001"/>
      </geometry>
      <origin rpy="3.1416 0 0" xyz="0 0 -0.0005"/>
      <material name="black">
        <color rgba="0.12 0.12 0.12 1"/>
      </material>
    </visual>
    <collision>
      <geometry>
        <mesh filename="package://sara_description/meshes/coude.STL" scale="0.001 0.001 0.001"/>
      </geometry>
      <origin rpy="3.1416 0 0" xyz="0 0 -0.0005"/>
    </collision>
    <inertial>
      <mass value="1"/>
      <origin rpy="0 3.1416 0" xyz="0 0 0"/>
      <inertia ixx="0.001" ixy="0" ixz="0" iyy="0.001" iyz="0" izz="0.001"/>
    </inertial>
  </link>
  <joint name="right_elbow_yaw_joint" type="revolute">
    <parent link="right_forearm_upper_link"/>
    <child link="right_forearm_lower_link"/>
    <limit effort="1000.0" lower="-3.1416" upper="3.1416" velocity="0.5"/>
    <origin rpy="1.5708 -1.5708 0" xyz="0 0.0945 0"/>
    <axis xyz="0 0 1"/>
  </joint>
  <link name="right_forearm_lower_link">
    <visual>
      <geometry>
        <mesh filename="package://sara_description/meshes/avant-bras.STL" scale="0.001 0.001 0.001"/>
      </geometry>
      <origin rpy="-1.5708 0 -1.5708" xyz="-0.0338 0.0338 0"/>
      <material name="black">
        <color rgba="0.12 0.12 0.12 1"/>
      </material>
    </visual>
    <collision>
      <geometry>
        <mesh filename="package://sara_description/meshes/avant-bras.STL" scale="0.001 0.001 0.001"/>
      </geometry>
      <origin rpy="-1.5708 0 -1.5708" xyz="-0.0338 0.0338 0"/>
    </collision>
    <inertial>
      <mass value="1"/>
      <origin rpy="-1.5708 0 -1.5708" xyz="-0.0676 0.0676 0"/>
      <inertia ixx="0.001" ixy="0" ixz="0" iyy="0.001" iyz="0" izz="0.001"/>
    </inertial>
  </link>
  <joint name="right_wrist_joint" type="fixed">
    <parent link="right_forearm_lower_link"/>
    <child link="right_upper_wrist_link"/>
    <limit effort="1000.0" lower="-3.1416" upper="3.1416" velocity="0.5"/>
    <origin rpy="1.5708 -1.5708 0" xyz="0 0 -0.11184"/>
    <axis xyz="0 1 0"/>
  </joint>
  <link name="right_upper_wrist_link">
    <visual>
      <geometry>
        <mesh filename="package://sara_description/meshes/poignet_haut.STL" scale="0.001 0.001 0.001"/>
      </geometry>
      <origin rpy="1.5708 -1.5708 0" xyz="0.0706 0.0283 -0.030"/>
      <material name="blue">
        <color rgba="0 0 1 .06"/>
      </material>
    </visual>
    <collision>
      <geometry>
        <mesh filename="package://sara_description/meshes/poignet_haut.STL" scale="0.001 0.001 0.001"/>
      </geometry>
      <origin rpy="1.5708 -1.5708 0" xyz="0.0706 0.0283 -0.030"/>
    </collision>
    <inertial>
      <mass value="1"/>
      <origin rpy="-1.5708 0 -1.5708" xyz="-0.0676 0.0676 0"/>
      <inertia ixx="0.001" ixy="0" ixz="0" iyy="0.001" iyz="0" izz="0.001"/>
    </inertial>
  </link>
  <joint name="right_wrist_pitch_joint" type="revolute">
    <parent link="right_upper_wrist_link"/>
    <child link="right_lower_wrist_link"/>
    <limit effort="1000.0" lower="-1.5708" upper="1.5708" velocity="0.5"/>
    <origin rpy="1.5708 -1.5708 0" xyz="0 0 0"/>
    <axis xyz="0 0 1"/>
  </joint>
  <link name="right_lower_wrist_link">
    <visual>
      <geometry>
        <mesh filename="package://sara_description/meshes/poignet_bas.STL" scale="0.001 0.001 0.001"/>
      </geometry>
      <origin rpy=" 0 1.5708 0" xyz="-0.02575  -0.01375 0.0305448"/>
      <material name="black">
        <color rgba="0.12 0.12 0.12 1"/>
      </material>
    </visual>
    <collision>
      <geometry>
        <mesh filename="package://sara_description/meshes/poignet_bas.STL" scale="0.001 0.001 0.001"/>
      </geometry>
      <origin rpy=" 0 1.5708 0" xyz="-0.02575  -0.01375 0.0305448"/>
    </collision>
    <inertial>
      <mass value="1"/>
      <origin rpy="-1.5708 0 -1.5708" xyz="-0.0676 0.0676 0"/>
      <inertia ixx="0.001" ixy="0" ixz="0" iyy="0.001" iyz="0" izz="0.001"/>
    </inertial>
  </link>
  <joint name="right_wrist_yaw_joint" type="revolute">
    <parent link="right_lower_wrist_link"/>
    <child link="right_socket_link"/>
    <limit effort="1000.0" lower="-1.49" upper="1.49" velocity="0.5"/>
    <origin rpy="1.5708 0 0" xyz="0 0.084375 0"/>
    <axis xyz="1 0 0"/>
  </joint>
  <link name="right_socket_link">
    <visual>
      <geometry>
        <mesh filename="package://sara_description/meshes/attache-pince.STL" scale="0.001 0.001 0.001"/>
      </geometry>
      <origin rpy="0 0 1.5708" xyz="0.028925 -0.025 -0.0362070"/>
      <material name="black">
        <color rgba="0.12 0.12 0.12 1"/>
      </material>
    </visual>
    <collision>
      <geometry>
        <mesh filename="package://sara_description/meshes/attache-pince.STL" scale="0.001 0.001 0.001"/>
      </geometry>
      <origin rpy="0 0 1.5708" xyz="0.028925 -0.025 -0.0362070"/>
    </collision>
    <inertial>
      <mass value="1"/>
      <origin rpy="-1.5708 0 -1.5708" xyz="-0.0676 0.0676 0"/>
      <inertia ixx="0.001" ixy="0" ixz="0" iyy="0.001" iyz="0" izz="0.001"/>
    </inertial>
  </link>
  <!-- End Effector -->
  <!-- Gripper 85 (round base)
    <xacro:include filename="$(find robotiq_85_description)/urdf/robotiq_85_gripper.urdf.xacro"/>
    <xacro:robotiq_85_gripper prefix="right_" parent="right_socket_link">
        <origin xyz="0 0 -0.02989" rpy="0 1.5708 0"/>
    </xacro:robotiq_85_gripper>-->
  <transmission name="right_robotiq_85_left_knuckle_trans">
    <type>transmission_interface/SimpleTransmission</type>
    <joint name="right_robotiq_85_left_knuckle_joint">
      <hardwareInterface>PositionJointInterface</hardwareInterface>
    </joint>
    <actuator name="right_robotiq_85_left_knuckle_motor">
      <mechanicalReduction>1</mechanicalReduction>
      <hardwareInterface>PositionJointInterface</hardwareInterface>
    </actuator>
  </transmission>
  <gazebo>
    <!-- loading plugin: mimic joints works in gazebo now -->
    <plugin filename="libroboticsgroup_gazebo_mimic_joint_plugin.so" name="right_mimic_robotiq_85_1">
      <joint>right_robotiq_85_left_knuckle_joint</joint>
      <mimicJoint>right_robotiq_85_right_knuckle_joint</mimicJoint>
      <!--multiplier>1.0</multiplier>
            <offset>0.0</offset-->
    </plugin>
    <plugin filename="libroboticsgroup_gazebo_mimic_joint_plugin.so" name="right_mimic_robotiq_85_2">
      <joint>right_robotiq_85_left_knuckle_joint</joint>
      <mimicJoint>right_robotiq_85_left_inner_knuckle_joint</mimicJoint>
      <!--multiplier>1.0</multiplier>
            <offset>0.0</offset-->
    </plugin>
    <plugin filename="libroboticsgroup_gazebo_mimic_joint_plugin.so" name="right_mimic_robotiq_85_3">
      <joint>right_robotiq_85_left_knuckle_joint</joint>
      <mimicJoint>right_robotiq_85_right_inner_knuckle_joint</mimicJoint>
      <!--multiplier>1.0</multiplier>
            <offset>0.0</offset-->
    </plugin>
    <plugin filename="libroboticsgroup_gazebo_mimic_joint_plugin.so" name="right_mimic_robotiq_85_4">
      <joint>right_robotiq_85_left_knuckle_joint</joint>
      <mimicJoint>right_robotiq_85_left_finger_tip_joint</mimicJoint>
      <multiplier>-1.0</multiplier>
      <offset>0.0</offset>
    </plugin>
    <plugin filename="libroboticsgroup_gazebo_mimic_joint_plugin.so" name="right_mimic_robotiq_85_5">
      <joint>right_robotiq_85_left_knuckle_joint</joint>
      <mimicJoint>right_robotiq_85_right_finger_tip_joint</mimicJoint>
      <multiplier>-1.0</multiplier>
      <offset>0.0</offset>
    </plugin>
  </gazebo>
  <!--  /\  -->
  <joint name="right_robotiq_85_base_joint" type="fixed">
    <parent link="right_socket_link"/>
    <child link="right_robotiq_85_base_link"/>
    <axis xyz="1 0 0"/>
    <origin rpy="0 1.5708 0" xyz="0 0 -0.02989"/>
  </joint>
  <!--  \/  -->
  <link name="right_robotiq_85_base_link">
    <visual>
      <geometry>
        <mesh filename="package://robotiq_c2_model_visualization/meshes/robotiq_c2/visual/robotiq_85_gripper_base.dae"/>
      </geometry>
      <origin rpy="3.1415 0 1.5707" xyz="0 0 0"/>
    </visual>
    <collision>
      <geometry>
        <mesh filename="package://robotiq_c2_model_visualization/meshes/robotiq_c2/collision/robotiq_85_gripper_base.dae"/>
      </geometry>
      <origin rpy="1.5707 0 1.5707" xyz="0 0 0"/>
    </collision>
    <inertial>
      <mass value="0.636951"/>
      <origin xyz="0.0 0.0 0.0"/>
      <inertia ixx="0.000380" ixy="0.000000" ixz="0.000000" iyx="0.000000" iyy="0.001110" iyz="0.000000" izx="0.000000" izy="0.000000" izz="0.001171"/>
    </inertial>
  </link>
  <!--  /\  -->
  <!--  /\  -->
  <joint name="right_robotiq_85_left_knuckle_joint" type="revolute">
    <parent link="right_robotiq_85_base_link"/>
    <child link="right_robotiq_85_left_knuckle_link"/>
    <axis xyz="1 0 0"/>
    <origin rpy="-1.5707 1.5707 0" xyz=".04191 .0306 0"/>
    <limit effort="1000" lower="0" upper=".8575" velocity="2.0"/>
  </joint>
  <joint name="right_robotiq_85_right_knuckle_joint" type="revolute">
    <parent link="right_robotiq_85_base_link"/>
    <child link="right_robotiq_85_right_knuckle_link"/>
    <axis xyz="1 0 0"/>
    <origin rpy="1.5707 -1.5707 0" xyz=".04191 -.0306 0"/>
    <limit effort="1000" lower="0" upper="1.5707" velocity="2.0"/>
    <mimic joint="right_robotiq_85_left_knuckle_joint" multiplier="1"/>
  </joint>
  <!--  \/  -->
  <!--  \/  -->
  <link name="right_robotiq_85_left_knuckle_link">
    <visual>
      <geometry>
        <mesh filename="package://robotiq_c2_model_visualization/meshes/robotiq_c2/visual/robotiq_85_gripper_joint_0_L.dae"/>
      </geometry>
      <origin rpy="3.14159 -1.5707 0" xyz="0 .04191 -.0306"/>
    </visual>
    <collision>
      <geometry>
        <mesh filename="package://robotiq_c2_model_visualization/meshes/robotiq_c2/collision/robotiq_85_gripper_joint_0_L.dae"/>
      </geometry>
      <origin rpy="1.5707 -1.5707 0" xyz="0 .04191 -.0306"/>
    </collision>
    <inertial>
      <mass value="0.018491"/>
      <origin xyz="0.0 0.0 0.0"/>
      <inertia ixx="0.000009" ixy="-0.000001" ixz="0.000000" iyx="-0.000001" iyy="0.000001" iyz="0.000000" izx="0.000000" izy="0.000000" izz="0.000010"/>
    </inertial>
  </link>
  <link name="right_robotiq_85_right_knuckle_link">
    <visual>
      <geometry>
        <mesh filename="package://robotiq_c2_model_visualization/meshes/robotiq_c2/visual/robotiq_85_gripper_joint_0_R.dae"/>
      </geometry>
      <origin rpy="3.14159 1.5707 0" xyz="0 .04191 -.0306"/>
    </visual>
    <collision>
      <geometry>
        <mesh filename="package://robotiq_c2_model_visualization/meshes/robotiq_c2/collision/robotiq_85_gripper_joint_0_R.dae"/>
      </geometry>
      <origin rpy="1.5707 1.5707 0" xyz="0 .04191 -.0306"/>
    </collision>
    <inertial>
      <mass value="0.018491"/>
      <origin xyz="0.0 0.0 0.0"/>
      <inertia ixx="0.000009" ixy="-0.000001" ixz="0.000000" iyx="-0.000001" iyy="0.000001" iyz="0.000000" izx="0.000000" izy="0.000000" izz="0.000010"/>
    </inertial>
  </link>
  <!--  /\  -->
  <!--  /\  -->
  <joint name="right_robotiq_85_left_finger_joint" type="fixed">
    <parent link="right_robotiq_85_left_knuckle_link"/>
    <child link="right_robotiq_85_left_finger_link"/>
    <axis xyz="1 0 0"/>
    <origin rpy="3.1415 0 0" xyz="0 .00508 .03134"/>
    <limit effort="1000" lower="0" upper="1.5707" velocity="2.0"/>
  </joint>
  <joint name="right_robotiq_85_right_finger_joint" type="fixed">
    <parent link="right_robotiq_85_right_knuckle_link"/>
    <child link="right_robotiq_85_right_finger_link"/>
    <axis xyz="1 0 0"/>
    <origin rpy="3.1415 0 0" xyz="0 .00508 .03134"/>
    <limit effort="1000" lower="0" upper="1.5707" velocity="2.0"/>
  </joint>
  <!--  \/  -->
  <!--  \/  -->
  <link name="right_robotiq_85_left_finger_link">
    <visual>
      <geometry>
        <mesh filename="package://robotiq_c2_model_visualization/meshes/robotiq_c2/visual/robotiq_85_gripper_joint_1_L.dae"/>
      </geometry>
      <origin rpy="0 1.5707 0" xyz="0 -.03683 .06194"/>
    </visual>
    <collision>
      <geometry>
        <mesh filename="package://robotiq_c2_model_visualization/meshes/robotiq_c2/collision/robotiq_85_gripper_joint_1_L.dae"/>
      </geometry>
      <origin rpy="-1.5707 1.5707 0" xyz="0 -.03683 .06194"/>
    </collision>
    <inertial>
      <mass value="0.027309"/>
      <origin xyz="0.0 0.0 0.0"/>
      <inertia ixx="0.000003" ixy="-0.000002" ixz="0.000000" iyx="-0.000002" iyy="0.000021" iyz="0.000000" izx="0.000000" izy="0.000000" izz="0.000020"/>
    </inertial>
  </link>
  <link name="right_robotiq_85_right_finger_link">
    <visual>
      <geometry>
        <mesh filename="package://robotiq_c2_model_visualization/meshes/robotiq_c2/visual/robotiq_85_gripper_joint_1_R.dae"/>
      </geometry>
      <origin rpy="0 -1.5707 0" xyz="0 -.03683 .06194"/>
    </visual>
    <collision>
      <geometry>
        <mesh filename="package://robotiq_c2_model_visualization/meshes/robotiq_c2/collision/robotiq_85_gripper_joint_1_R.dae"/>
      </geometry>
      <origin rpy="-1.5707 -1.5707 0" xyz="0 -.03683 .06194"/>
    </collision>
    <inertial>
      <mass value="0.027309"/>
      <origin xyz="0.0 0.0 0.0"/>
      <inertia ixx="0.000003" ixy="-0.000002" ixz="0.000000" iyx="-0.000002" iyy="0.000021" iyz="0.000000" izx="0.000000" izy="0.000000" izz="0.000020"/>
    </inertial>
  </link>
  <!--  /\  -->
  <!--  /\  -->
  <joint name="right_robotiq_85_left_inner_knuckle_joint" type="revolute">
    <parent link="right_robotiq_85_base_link"/>
    <child link="right_robotiq_85_left_inner_knuckle_link"/>
    <axis xyz="1 0 0"/>
    <origin rpy="1.5707 1.5707 0" xyz=".04843 .0127 0"/>
    <limit effort="1000" lower="0" upper="1.5707" velocity="2.0"/>
    <mimic joint="right_robotiq_85_left_knuckle_joint" offset="0"/>
  </joint>
  <joint name="right_robotiq_85_right_inner_knuckle_joint" type="revolute">
    <parent link="right_robotiq_85_base_link"/>
    <child link="right_robotiq_85_right_inner_knuckle_link"/>
    <axis xyz="1 0 0"/>
    <origin rpy="-1.5707 -1.5707 0" xyz=".04843 -.0127 0"/>
    <limit effort="1000" lower="0" upper="1.5707" velocity="2.0"/>
    <mimic joint="right_robotiq_85_left_knuckle_joint" offset="0"/>
  </joint>
  <!--  \/  -->
  <!--  \/  -->
  <link name="right_robotiq_85_left_inner_knuckle_link">
    <visual>
      <geometry>
        <mesh filename="package://robotiq_c2_model_visualization/meshes/robotiq_c2/visual/robotiq_85_gripper_joint_2_L.dae"/>
      </geometry>
      <origin rpy="0 1.5707 0" xyz="0 -.04843 .0127"/>
    </visual>
    <collision>
      <geometry>
        <mesh filename="package://robotiq_c2_model_visualization/meshes/robotiq_c2/collision/robotiq_85_gripper_joint_2_L.dae"/>
      </geometry>
      <origin rpy="-1.5707 1.5707 0" xyz="0 -.04843 .0127"/>
    </collision>
    <inertial>
      <mass value="0.029951"/>
      <origin xyz="0.0 0.0 0.0"/>
      <inertia ixx="0.000039" ixy="0.000000" ixz="0.000000" iyx="0.000000" iyy="0.000005" iyz="0.000000" izx="0.000000" izy="0.000000" izz="0.000035"/>
    </inertial>
  </link>
  <link name="right_robotiq_85_right_inner_knuckle_link">
    <visual>
      <geometry>
        <mesh filename="package://robotiq_c2_model_visualization/meshes/robotiq_c2/visual/robotiq_85_gripper_joint_2_R.dae"/>
      </geometry>
      <origin rpy="0 -1.5707 0" xyz="0 -.04843 .0127"/>
    </visual>
    <collision>
      <geometry>
        <mesh filename="package://robotiq_c2_model_visualization/meshes/robotiq_c2/collision/robotiq_85_gripper_joint_2_R.dae"/>
      </geometry>
      <origin rpy="-1.5707 -1.5707 0" xyz="0 -.04843 .0127"/>
    </collision>
    <inertial>
      <mass value="0.029951"/>
      <origin xyz="0.0 0.0 0.0"/>
      <inertia ixx="0.000039" ixy="0.000000" ixz="0.000000" iyx="0.000000" iyy="0.000005" iyz="0.000000" izx="0.000000" izy="0.000000" izz="0.000035"/>
    </inertial>
  </link>
  <!--  /\  -->
  <!--  /\  -->
  <joint name="right_robotiq_85_left_finger_tip_joint" type="revolute">
    <parent link="right_robotiq_85_left_inner_knuckle_link"/>
    <child link="right_robotiq_85_left_finger_tip_link"/>
    <axis xyz="1 0 0"/>
    <origin rpy="0 0 0" xyz="0 .04196 -.0388"/>
    <limit effort="1000" lower="0" upper="1.5707" velocity="2.0"/>
    <mimic joint="right_robotiq_85_left_knuckle_joint" multiplier="-1"/>
  </joint>
  <joint name="right_robotiq_85_right_finger_tip_joint" type="revolute">
    <parent link="right_robotiq_85_right_inner_knuckle_link"/>
    <child link="right_robotiq_85_right_finger_tip_link"/>
    <axis xyz="1 0 0"/>
    <origin rpy="0 0 0" xyz="0 .04196 -.0388"/>
    <limit effort="1000" lower="0" upper="1.5707" velocity="2.0"/>
    <mimic joint="right_robotiq_85_left_knuckle_joint" multiplier="-1"/>
  </joint>
  <!--  \/  -->
  <!--  \/  -->
  <link name="right_robotiq_85_left_finger_tip_link">
    <visual>
      <geometry>
        <mesh filename="package://robotiq_c2_model_visualization/meshes/robotiq_c2/visual/robotiq_85_gripper_joint_3_L.dae"/>
      </geometry>
      <origin rpy="0 1.5707 0" xyz="0 -.090381 .051505"/>
    </visual>
    <collision>
      <geometry>
        <mesh filename="package://robotiq_c2_model_visualization/meshes/robotiq_c2/collision/robotiq_85_gripper_joint_3_L.dae"/>
      </geometry>
      <origin rpy="-1.5707 1.5707 0" xyz="0 -.090381 .051505"/>
    </collision>
    <inertial>
      <mass value="0.019555"/>
      <origin xyz="0.0 0.0 0.0"/>
      <inertia ixx="0.000002" ixy="0.000000" ixz="0.000000" iyx="0.000000" iyy="0.000005" iyz="0.000000" izx="0.000000" izy="0.000000" izz="0.000006"/>
    </inertial>
  </link>
  <link name="right_robotiq_85_right_finger_tip_link">
    <visual>
      <geometry>
        <mesh filename="package://robotiq_c2_model_visualization/meshes/robotiq_c2/visual/robotiq_85_gripper_joint_3_R.dae"/>
      </geometry>
      <origin rpy="0 -1.5707 0" xyz="0 -.090381 .051505"/>
    </visual>
    <collision>
      <geometry>
        <mesh filename="package://robotiq_c2_model_visualization/meshes/robotiq_c2/collision/robotiq_85_gripper_joint_3_R.dae"/>
      </geometry>
      <origin rpy="-1.5707 -1.5707 0" xyz="0 -.090381 .051505"/>
    </collision>
    <inertial>
      <mass value="0.019555"/>
      <origin xyz="0.0 0.0 0.0"/>
      <inertia ixx="0.000002" ixy="0.000000" ixz="0.000000" iyx="0.000000" iyy="0.000005" iyz="0.000000" izx="0.000000" izy="0.000000" izz="0.000006"/>
    </inertial>
  </link>
</robot>
