<?xml version="1.0" ?>
<!-- =================================================================================== -->
<!-- |    This document was autogenerated by xacro from sara.urdf.xacro                | -->
<!-- |    EDITING THIS FILE BY HAND IS NOT RECOMMENDED                                 | -->
<!-- =================================================================================== -->
<robot name="sara" xmlns:xacro="http://ros.org/wiki/xacro">
  <gazebo reference="{name}_link">
    <turnGravityOff>false</turnGravityOff>
  </gazebo>
  <gazebo reference="spine_link">
    <turnGravityOff>false</turnGravityOff>
  </gazebo>
  <!-- hokuyo -->
  <gazebo reference="lidar_link">
    <turnGravityOff>false</turnGravityOff>
    <sensor name="base_hokuyo_sensor" type="ray">
      <pose>0 0 0 0 0 0</pose>
      <visualize>true</visualize>
      <update_rate>30</update_rate>
      <ray>
        <scan>
          <horizontal>
            <samples>720</samples>
            <resolution>1</resolution>
            <min_angle>-1.57</min_angle>
            <max_angle>1.57</max_angle>
          </horizontal>
        </scan>
        <range>
          <min>0.10</min>
          <max>30.0</max>
          <resolution>0.01</resolution>
        </range>
        <noise>
          <type>gaussian</type>
          <!-- Noise parameters based on published spec for Hokuyo laser
                                      achieving "+-30mm" accuracy at range < 10m.  A mean of 0.0m and
                                      stddev of 0.01m will put 99.7% of samples within 0.03m of the true
                                      reading. -->
          <mean>0.0</mean>
          <stddev>0.01</stddev>
        </noise>
      </ray>
      <plugin filename="libgazebo_ros_laser.so" name="gazebo_ros_base_hokuyo_controller">
        <topicName>/laser/scan</topicName>
        <frameName>lidar_link</frameName>
      </plugin>
    </sensor>
  </gazebo>
  <gazebo>
    <plugin filename="libgazebo_ros_planar_move.so" name="object_controller">
      <commandTopic>/cmd_vel</commandTopic>
      <odometryTopic>/odom</odometryTopic>
      <odometryFrame>odom</odometryFrame>
      <odometryRate>20.0</odometryRate>
      <robotBaseFrame>base_link</robotBaseFrame>
    </plugin>
  </gazebo>
  <link name="base_link">
    <visual>
      <geometry>
        <mesh filename="package://sara_description/meshes/base.STL" scale="0.001 0.001 0.001"/>
      </geometry>
      <origin rpy="-1.57 0 1.57" xyz="0.295 -0.250 0.85635"/>
      <material name="black">
        <color rgba="0.12 0.12 0.12 1"/>
      </material>
    </visual>
    <visual>
      <geometry>
        <box size="0.4 0.35635 0.454"/>
      </geometry>
      <origin rpy="0 0 0" xyz="-0.055 0 0.227"/>
      <material name="black">
        <color rgba="0.12 0.12 0.12 1"/>
      </material>
    </visual>
    <collision>
      <geometry>
        <mesh filename="package://sara_description/meshes/base.STL" scale="0.001 0.001 0.001"/>
      </geometry>
      <origin rpy="-1.57 0 1.57" xyz="0.295 -0.250 0.85635"/>
    </collision>
    <collision>
      <geometry>
        <box size="0.4 0.35635 0.454"/>
      </geometry>
      <origin rpy="0 0 0" xyz="-0.055 0 0.227"/>
    </collision>
    <inertial>
      <mass value="100"/>
      <origin rpy="0 0 0" xyz="-0.055 0 0.227"/>
      <inertia ixx="0.1" ixy="0.1" ixz="0.1" iyy="0.1" iyz="0.1" izz="0.1"/>
    </inertial>
    <inertial>
      <mass value="30"/>
      <origin rpy="0 0 0" xyz="0 0 0"/>
      <inertia ixx="0.1" ixy="0.1" ixz="0.1" iyy="0.1" iyz="0.1" izz="0.1"/>
    </inertial>
  </link>
  <!-- Lidar -->
  <link name="lidar_link">
    <visual>
      <geometry>
        <cylinder length="0.085" radius="0.03"/>
      </geometry>
      <origin rpy="0 0 0" xyz="0 0 0.0425"/>
      <material name="orange">
        <color rgba="1 0.5 0 1"/>
      </material>
    </visual>
    <collision>
      <geometry>
        <cylinder length="0.085" radius="0.03"/>
      </geometry>
      <origin rpy="0 0 0" xyz="0 0 0"/>
    </collision>
    <inertial>
      <mass value="0.5"/>
      <origin rpy="0 0 0" xyz="0 0 0"/>
      <inertia ixx="0.001" ixy="0" ixz="0" iyy="0.001" iyz="0" izz="0.001"/>
    </inertial>
  </link>
  <joint name="laser_joint" type="fixed">
    <parent link="base_link"/>
    <child link="lidar_link"/>
    <origin rpy="0 0 0" xyz="0.2516879 0 -0.0288348"/>
  </joint>
  <link name="front_left_wheel">
      </link>
  <joint name="base_to_front_left_wheel" type="continuous">
    <parent link="base_link"/>
    <child link="front_left_wheel"/>
    <axis xyz="0 0 1"/>
    <origin rpy=" -1.57079632679 0 0" xyz="0.205631 0.22735 -0.06"/>
  </joint>
  <link name="front_right_wheel">
      </link>
  <joint name="base_to_front_right_wheel" type="continuous">
    <parent link="base_link"/>
    <child link="front_right_wheel"/>
    <axis xyz="0 0 1"/>
    <origin rpy=" 1.57079632679 0 0" xyz="0.205631 -0.22735 -0.06"/>
  </joint>
  <link name="rear_left_wheel">
      </link>
  <joint name="base_to_rear_left_wheel" type="continuous">
    <parent link="base_link"/>
    <child link="rear_left_wheel"/>
    <axis xyz="0 0 1"/>
    <origin rpy=" -1.57079632679 0 0" xyz="-0.255631 0.22735 -0.06"/>
  </joint>
  <link name="rear_right_wheel">
      </link>
  <joint name="base_to_rear_right_wheel" type="continuous">
    <parent link="base_link"/>
    <child link="rear_right_wheel"/>
    <axis xyz="0 0 1"/>
    <origin rpy=" 1.57079632679 0 0" xyz="-0.255631 -0.22735 -0.06"/>
  </joint>
  <gazebo reference="kinect_link">
    <turnGravityOff>false</turnGravityOff>
  </gazebo>
  <link name="kinect_link">
    <visual>
      <geometry>
        <mesh filename="package://sara_description/meshes/kinect.STL" scale="0.001 0.001 0.001"/>
      </geometry>
      <origin rpy="1.5708 0 0" xyz="-0.13466 0 -0.028975"/>
      <material name="black">
        <color rgba="0.12 0.12 0.12 1"/>
      </material>
    </visual>
    <collision>
      <geometry>
        <mesh filename="package://sara_description/meshes/kinect.STL" scale="0.001 0.001 0.001"/>
      </geometry>
      <origin rpy="0 0 -1.5708" xyz="-0.0269875 0.1321628 0"/>
    </collision>
    <inertial>
      <mass value="10"/>
      <origin rpy="1.5708 0 1.5708" xyz="0 0 0"/>
      <inertia ixx="0.001" ixy="0" ixz="0" iyy="0.001" iyz="0" izz="0.001"/>
    </inertial>
  </link>
  <joint name="base_kinect_joint" type="fixed">
    <parent link="base_link"/>
    <child link="kinect_link"/>
    <limit effort="1000.0" lower="0" upper="0.5" velocity="0.2"/>
    <origin rpy="-1.5708 0 -1.5708" xyz="0.177374 0 0.65676"/>
    <axis xyz="0 0 1"/>
  </joint>
  <gazebo reference="torso_link">
    <turnGravityOff>false</turnGravityOff>
  </gazebo>
  <link name="torso_link">
    <visual>
      <geometry>
        <mesh filename="package://sara_description/meshes/torse.STL" scale="0.001 0.001 0.001"/>
      </geometry>
      <origin rpy="1.5708 0 1.5708" xyz="-0.14427 -0.197233 0"/>
      <material name="black">
        <color rgba="0.12 0.12 0.12 1"/>
      </material>
    </visual>
    <collision>
      <geometry>
        <mesh filename="package://sara_description/meshes/torse.STL" scale="0.001 0.001 0.001"/>
      </geometry>
      <origin rpy="1.5708 0 1.5708" xyz="-0.14427 -0.197233 0"/>
    </collision>
    <inertial>
      <mass value="10"/>
      <origin rpy="1.5708 0 1.5708" xyz="-0.14427 -0.197233 0"/>
      <inertia ixx="0.001" ixy="0" ixz="0" iyy="0.001" iyz="0" izz="0.001"/>
    </inertial>
  </link>
  <joint name="base_torso_joint" type="fixed">
    <parent link="base_link"/>
    <child link="torso_link"/>
    <limit effort="1000.0" lower="0" upper="0.5" velocity="0.2"/>
    <origin rpy="0 0 0" xyz="0.177374 0 0.70531"/>
    <axis xyz="0 0 1"/>
  </joint>
  <gazebo reference="neck_link">
    <turnGravityOff>false</turnGravityOff>
  </gazebo>
  <link name="neck_link">
    <visual>
      <geometry>
        <mesh filename="package://sara_description/meshes/cou.STL" scale="0.001 0.001 0.001"/>
      </geometry>
      <origin rpy="1.5708 0 1.5708" xyz="0 0 0"/>
      <material name="blue">
        <color rgba="0.06 0.06 1 1"/>
      </material>
    </visual>
    <collision>
      <geometry>
        <mesh filename="package://sara_description/meshes/cou.STL" scale="0.001 0.001 0.001"/>
      </geometry>
      <origin rpy="1.5708 0 1.5708" xyz="0 0 0"/>
    </collision>
    <inertial>
      <mass value="2"/>
      <origin rpy="1.5708 0 1.5708" xyz="0 0 0"/>
      <inertia ixx="0.001" ixy="0" ixz="0" iyy="0.001" iyz="0" izz="0.001"/>
    </inertial>
  </link>
  <joint name="torso_neck_joint" type="revolute">
    <parent link="torso_link"/>
    <child link="neck_link"/>
    <limit effort="1000.0" lower="-1.22173" upper="1.22173" velocity="0.5"/>
    <!-- 1mm ajoute en z (collision) -->
    <origin rpy="0 0 0" xyz="0.032295 0 0.2777"/>
    <axis xyz="0 0 1"/>
  </joint>
  <gazebo reference="neck_dynamixel_link">
    <turnGravityOff>false</turnGravityOff>
  </gazebo>
  <gazebo reference="head_link">
    <turnGravityOff>false</turnGravityOff>
  </gazebo>
  <gazebo reference="camera_link">
    <turnGravityOff>false</turnGravityOff>
    <sensor name="camera" type="depth">
      <visualize>true</visualize>
      <pose>0 0 0 0 0 0</pose>
      <always_on>true</always_on>
      <update_rate>20.0</update_rate>
      <camera>
        <horizontal_fov>1.3962634</horizontal_fov>
        <image>
          <format>R8G8B8</format>
          <width>640</width>
          <height>480</height>
        </image>
        <clip>
          <near>0.05</near>
          <far>8.0</far>
        </clip>
      </camera>
      <plugin filename="libgazebo_ros_openni_kinect.so" name="kinect_camera_controller">
        <cameraName>camera</cameraName>
        <alwaysOn>true</alwaysOn>
        <updateRate>5</updateRate>
        <imageTopicName>rgb/image_raw</imageTopicName>
        <depthImageTopicName>depth/image_raw</depthImageTopicName>
        <pointCloudTopicName>depth/points</pointCloudTopicName>
        <cameraInfoTopicName>rgb/camera_info</cameraInfoTopicName>
        <depthImageCameraInfoTopicName>depth/camera_info</depthImageCameraInfoTopicName>
        <frameName>camera/camera_rgb_optical_frame</frameName>
        <baseline>0.1</baseline>
        <distortion_k1>0.0</distortion_k1>
        <distortion_k2>0.0</distortion_k2>
        <distortion_k3>0.0</distortion_k3>
        <distortion_t1>0.0</distortion_t1>
        <distortion_t2>0.0</distortion_t2>
        <pointCloudCutoff>0.4</pointCloudCutoff>
      </plugin>
    </sensor>
  </gazebo>
  <link name="head_link">
    <visual>
      <geometry>
        <mesh filename="package://sara_description/meshes/tete.STL" scale="0.001 0.001 0.001"/>
      </geometry>
      <origin rpy="1.5708 -1.5708 1.5708" xyz="0 0 0"/>
      <material name="blue">
        <color rgba="0.06 0.06 1 1"/>
      </material>
    </visual>
    <collision>
      <geometry>
        <mesh filename="package://sara_description/meshes/tete.STL" scale="0.001 0.001 0.001"/>
      </geometry>
      <origin rpy="1.5708 -1.5708 1.5708" xyz="0 0 0"/>
    </collision>
    <inertial>
      <mass value="5"/>
      <origin rpy="1.5708 0 1.5708" xyz="0 0 0"/>
      <inertia ixx="0.001" ixy="0" ixz="0" iyy="0.001" iyz="0" izz="0.001"/>
    </inertial>
  </link>
  <link name="head_dynamixel_link">
    <visual>
      <geometry>
        <cylinder length="0.015" radius="0.02"/>
      </geometry>
      <origin rpy="0 0 0" xyz="0 0 0.018"/>
      <material name="blue">
        <color rgba="0 0 1 1"/>
      </material>
    </visual>
    <inertial>
      <mass value="5"/>
      <origin rpy="0 0 0" xyz="0 0 0.018"/>
      <inertia ixx="0.001" ixy="0" ixz="0" iyy="0.001" iyz="0" izz="0.001"/>
    </inertial>
  </link>
  <joint name="head_dynamixel_joint" type="revolute">
    <parent link="head_link"/>
    <child link="head_dynamixel_link"/>
    <limit effort="1000.0" lower="-1.5" upper="1.5" velocity="0.5"/>
    <origin rpy="3.1416 0 0" xyz="0 -0.054 0"/>
    <axis xyz="0 0 1"/>
  </joint>
  <joint name="neck_head_joint" type="revolute">
    <parent link="neck_link"/>
    <child link="head_link"/>
    <limit effort="1000.0" lower="-0.40" upper="1.04" velocity="0.5"/>
    <origin rpy="-1.57 0 0" xyz="0 0 0.0927"/>
    <axis xyz="0 0 1"/>
  </joint>
  <!-- xtion -->
  <link name="camera_link">
    <visual>
      <geometry>
        <mesh filename="package://sara_description/meshes/xtion.STL" scale="0.001 0.001 0.001"/>
      </geometry>
      <origin rpy="1.5708 0 1.5708" xyz="0 0 0"/>
      <material name="black"/>
    </visual>
    <collision>
      <geometry>
        <mesh filename="package://sara_description/meshes/xtion.STL" scale="0.001 0.001 0.001"/>
      </geometry>
      <origin rpy="1.5708 0 1.5708" xyz="0 0 0"/>
    </collision>
    <inertial>
      <mass value="0.5"/>
      <origin rpy="1.5708 0 1.5708" xyz="0 0 0"/>
      <inertia ixx="0.001" ixy="0" ixz="0" iyy="0.001" iyz="0" izz="0.001"/>
    </inertial>
  </link>
  <joint name="camera_joint" type="fixed">
    <parent link="head_link"/>
    <child link="camera_link"/>
    <origin rpy="1.57 0 0" xyz="0.0776104 -0.13 0"/>
    <axis xyz="0 1 0"/>
  </joint>
  <transmission name="torso_arm_trans" type="SimpleTransmission">
    <type>transmission_interface/SimpleTransmission</type>
    <actuator name="torso_arm_motor">
      <mechanicalReduction>1</mechanicalReduction>
    </actuator>
    <joint name="torso_arm_joint">
      <hardwareInterface>VelocityJointInterface</hardwareInterface>
    </joint>
  </transmission>
  <gazebo reference="arm_clavicular_link">
    <turnGravityOff>false</turnGravityOff>
  </gazebo>
  <transmission name="arm_shoulder_trans" type="SimpleTransmission">
    <type>transmission_interface/SimpleTransmission</type>
    <actuator name="arm_shoulder_motor">
      <mechanicalReduction>1</mechanicalReduction>
    </actuator>
    <joint name="arm_shoulder_joint">
      <hardwareInterface>VelocityJointInterface</hardwareInterface>
    </joint>
  </transmission>
  <gazebo reference="${name}_fix_upper_link">
    <turnGravityOff>false</turnGravityOff>
  </gazebo>
  <transmission name="arm_rot_elbow_trans" type="SimpleTransmission">
    <type>transmission_interface/SimpleTransmission</type>
    <actuator name="arm_rot_elbow_motor">
      <mechanicalReduction>1</mechanicalReduction>
    </actuator>
    <joint name="arm_rot_elbow_joint">
      <hardwareInterface>VelocityJointInterface</hardwareInterface>
    </joint>
  </transmission>
  <gazebo reference="arm_rot_upper_link">
    <turnGravityOff>false</turnGravityOff>
  </gazebo>
  <transmission name="arm_elbow_trans" type="SimpleTransmission">
    <type>transmission_interface/SimpleTransmission</type>
    <actuator name="arm_elbow_motor">
      <mechanicalReduction>1</mechanicalReduction>
    </actuator>
    <joint name="arm_elbow_joint">
      <hardwareInterface>VelocityJointInterface</hardwareInterface>
    </joint>
  </transmission>
  <gazebo reference="arm_fix_lower_link">
    <turnGravityOff>false</turnGravityOff>
  </gazebo>
  <transmission name="arm_rot_wrist_trans" type="SimpleTransmission">
    <type>transmission_interface/SimpleTransmission</type>
    <actuator name="arm_rot_wrist_motor">
      <mechanicalReduction>1</mechanicalReduction>
    </actuator>
    <joint name="arm_rot_wrist_joint">
      <hardwareInterface>VelocityJointInterface</hardwareInterface>
    </joint>
  </transmission>
  <gazebo reference="arm_rot_lower_link">
    <turnGravityOff>false</turnGravityOff>
  </gazebo>
  <transmission name="arm_forarm-wrist_trans" type="SimpleTransmission">
    <type>transmission_interface/SimpleTransmission</type>
    <actuator name="arm_forarm-wrist_motor">
      <mechanicalReduction>1</mechanicalReduction>
    </actuator>
    <joint name="arm_forarm_wrist_joint">
      <hardwareInterface>VelocityJointInterface</hardwareInterface>
    </joint>
  </transmission>
  <gazebo reference="arm_high_wrist_link">
    <turnGravityOff>false</turnGravityOff>
  </gazebo>
  <transmission name="arm_high_low_wrist_trans" type="SimpleTransmission">
    <type>transmission_interface/SimpleTransmission</type>
    <actuator name="arm_high_low_wrist_motor">
      <mechanicalReduction>1</mechanicalReduction>
    </actuator>
    <joint name="arm_high_low_wrist_joint">
      <hardwareInterface>VelocityJointInterface</hardwareInterface>
    </joint>
  </transmission>
  <gazebo reference="arm_low_wrist_link">
    <turnGravityOff>false</turnGravityOff>
  </gazebo>
  <transmission name="arm_low_wrist_grasp_socket_trans" type="SimpleTransmission">
    <type>transmission_interface/SimpleTransmission</type>
    <actuator name="arm_low_wrist_grasp_socket_motor">
      <mechanicalReduction>1</mechanicalReduction>
    </actuator>
    <joint name="arm_low_wrist_grasp_socket_joint">
      <hardwareInterface>VelocityJointInterface</hardwareInterface>
    </joint>
  </transmission>
  <gazebo reference="arm_socket_link">
    <turnGravityOff>false</turnGravityOff>
  </gazebo>
  <transmission name="arm_end_effector_trans" type="SimpleTransmission">
    <type>transmission_interface/SimpleTransmission</type>
    <actuator name="arm_end_effector_motor">
      <mechanicalReduction>1</mechanicalReduction>
    </actuator>
    <joint name="arm_end_effector_joint">
      <hardwareInterface>VelocityJointInterface</hardwareInterface>
    </joint>
  </transmission>
  <gazebo reference="grasp_link">
    <turnGravityOff>false</turnGravityOff>
  </gazebo>
  <gazebo>
    <plugin filename="libgazebo_ros_control.so" name="gazebo_ros_control">
      <robotNamespace>/</robotNamespace>
    </plugin>
  </gazebo>
  <joint name="torso_arm_joint" type="revolute">
    <parent link="torso_link"/>
    <child link="arm_clavicular_link"/>
    <limit effort="1000.0" lower="-0.18" upper="1.21" velocity="0.5"/>
    <origin rpy="0 -1.57 0" xyz="0 -0.145 0.189"/>
    <axis xyz="0 0 1"/>
  </joint>
  <link name="arm_clavicular_link">
    <visual>
      <geometry>
        <mesh filename="package://sara_description/meshes/epaule.STL" scale="0.001 0.001 0.001"/>
      </geometry>
      <origin rpy="0 3.1416 0" xyz="0 0 0"/>
      <material name="black">
        <color rgba="0.12 0.12 0.12 1"/>
      </material>
    </visual>
    <collision>
      <geometry>
        <mesh filename="package://sara_description/meshes/epaule.STL" scale="0.001 0.001 0.001"/>
      </geometry>
      <origin rpy="0 3.1416 0" xyz="0 0 0"/>
    </collision>
    <inertial>
      <mass value="1"/>
      <origin rpy="0 3.1416 0" xyz="0 0 0"/>
      <inertia ixx="0.001" ixy="0" ixz="0" iyy="0.001" iyz="0" izz="0.001"/>
    </inertial>
  </link>
  <joint name="arm_shoulder_joint" type="revolute">
    <parent link="arm_clavicular_link"/>
    <child link="arm_fix_upper_link"/>
    <limit effort="1000.0" lower="-3.29" upper="0.37" velocity="0.5"/>
    <origin rpy="-1.57 0 0" xyz="0 -0.085 0"/>
    <axis xyz="0 0 1"/>
  </joint>
  <link name="arm_fix_upper_link">
    <visual>
      <geometry>
        <mesh filename="package://sara_description/meshes/epaule.STL" scale="0.001 0.001 0.001"/>
      </geometry>
      <origin rpy="3.1416 0 1.5708" xyz="0 0 0"/>
      <material name="black">
        <color rgba="0.12 0.12 0.12 1"/>
      </material>
    </visual>
    <collision>
      <geometry>
        <mesh filename="package://sara_description/meshes/epaule.STL" scale="0.001 0.001 0.001"/>
      </geometry>
      <origin rpy="3.1416 0 1.5708" xyz="0 0 0"/>
    </collision>
    <inertial>
      <mass value="1"/>
      <origin rpy="3.1416 0 1.5708" xyz="0 0 0"/>
      <inertia ixx="0.001" ixy="0" ixz="0" iyy="0.001" iyz="0" izz="0.001"/>
    </inertial>
  </link>
  <joint name="arm_rot_elbow_joint" type="revolute">
    <parent link="arm_fix_upper_link"/>
    <child link="arm_rot_upper_link"/>
    <limit effort="1000.0" lower="-2.14" upper="1.00" velocity="0.5"/>
    <origin rpy="1.5708 0 1.5708" xyz="-0.085 0 0"/>
    <axis xyz="0 0 1"/>
  </joint>
  <link name="arm_rot_upper_link">
    <visual>
      <geometry>
        <mesh filename="package://sara_description/meshes/bras_haut.STL" scale="0.001 0.001 0.001"/>
      </geometry>
      <origin rpy="1.5708 3.1416 3.1416" xyz="0 0 0"/>
      <material name="black">
        <color rgba="0.12 0.12 0.12 1"/>
      </material>
    </visual>
    <collision>
      <geometry>
        <mesh filename="package://sara_description/meshes/bras_haut.STL" scale="0.001 0.001 0.001"/>
      </geometry>
      <origin rpy="1.5708 3.1416 3.1416" xyz="0 0 0"/>
    </collision>
    <inertial>
      <mass value="1"/>
      <origin rpy="1.5708 3.1416 3.1416" xyz="0 0 0"/>
      <inertia ixx="0.001" ixy="0" ixz="0" iyy="0.001" iyz="0" izz="0.001"/>
    </inertial>
  </link>
  <joint name="arm_elbow_joint" type="revolute">
    <parent link="arm_rot_upper_link"/>
    <child link="arm_fix_lower_link"/>
    <limit effort="1000.0" lower="-2.20" upper="1.90" velocity="0.5"/>
    <origin rpy="-1.5708 0 0" xyz="0 0 -0.31"/>
    <axis xyz="0 0 1"/>
  </joint>
  <link name="arm_fix_lower_link">
    <visual>
      <geometry>
        <mesh filename="package://sara_description/meshes/coude.STL" scale="0.001 0.001 0.001"/>
      </geometry>
      <origin rpy="3.1416 0 0" xyz="0 0 -0.0005"/>
      <material name="black">
        <color rgba="0.12 0.12 0.12 1"/>
      </material>
    </visual>
    <collision>
      <geometry>
        <mesh filename="package://sara_description/meshes/coude.STL" scale="0.001 0.001 0.001"/>
      </geometry>
      <origin rpy="3.1416 0 0" xyz="0 0 -0.0005"/>
    </collision>
    <inertial>
      <mass value="1"/>
      <origin rpy="0 3.1416 0" xyz="0 0 0"/>
      <inertia ixx="0.001" ixy="0" ixz="0" iyy="0.001" iyz="0" izz="0.001"/>
    </inertial>
  </link>
  <joint name="arm_rot_wrist_joint" type="revolute">
    <parent link="arm_fix_lower_link"/>
    <child link="arm_rot_lower_link"/>
    <limit effort="1000.0" lower="-3.1416" upper="3.1416" velocity="0.5"/>
    <origin rpy="1.5708 -1.5708 0" xyz="0 0.0945 0"/>
    <axis xyz="0 0 1"/>
  </joint>
  <link name="arm_rot_lower_link">
    <visual>
      <geometry>
        <mesh filename="package://sara_description/meshes/avant-bras.STL" scale="0.001 0.001 0.001"/>
      </geometry>
      <origin rpy="-1.5708 0 -1.5708" xyz="-0.0338 0.0338 0"/>
      <material name="black">
        <color rgba="0.12 0.12 0.12 1"/>
      </material>
    </visual>
    <collision>
      <geometry>
        <mesh filename="package://sara_description/meshes/avant-bras.STL" scale="0.001 0.001 0.001"/>
      </geometry>
      <origin rpy="-1.5708 0 -1.5708" xyz="-0.0338 0.0338 0"/>
    </collision>
    <inertial>
      <mass value="1"/>
      <origin rpy="-1.5708 0 -1.5708" xyz="-0.0676 0.0676 0"/>
      <inertia ixx="0.001" ixy="0" ixz="0" iyy="0.001" iyz="0" izz="0.001"/>
    </inertial>
  </link>
  <joint name="arm_forarm_wrist_joint" type="fixed">
    <parent link="arm_rot_lower_link"/>
    <child link="arm_high_wrist_link"/>
    <limit effort="1000.0" lower="-3.1416" upper="3.1416" velocity="0.5"/>
    <origin rpy="1.5708 -1.5708 0" xyz="0 0 -0.11184"/>
    <axis xyz="0 1 0"/>
  </joint>
  <link name="arm_high_wrist_link">
    <visual>
      <geometry>
        <mesh filename="package://sara_description/meshes/poignet_haut.STL" scale="0.001 0.001 0.001"/>
      </geometry>
      <origin rpy="1.5708 -1.5708 0" xyz="0.0706 0.0283 -0.030"/>
      <material name="blue">
        <color rgba="0 0 1 .06"/>
      </material>
    </visual>
    <collision>
      <geometry>
        <mesh filename="package://sara_description/meshes/poignet_haut.STL" scale="0.001 0.001 0.001"/>
      </geometry>
      <origin rpy="1.5708 -1.5708 0" xyz="0.0706 0.0283 -0.030"/>
    </collision>
  </link>
  <joint name="arm_high_low_wrist_joint" type="revolute">
    <parent link="arm_high_wrist_link"/>
    <child link="arm_low_wrist_link"/>
    <limit effort="1000.0" lower="-3.1416" upper="3.1416" velocity="0.5"/>
    <origin rpy="1.5708 -1.5708 0" xyz="0 0 0"/>
    <axis xyz="0 0 1"/>
  </joint>
  <link name="arm_low_wrist_link">
    <visual>
      <geometry>
        <mesh filename="package://sara_description/meshes/poignet_bas.STL" scale="0.001 0.001 0.001"/>
      </geometry>
      <origin rpy=" 0 1.5708 0" xyz="-0.02575  -0.01375 0.0305448"/>
      <material name="black">
        <color rgba="0.12 0.12 0.12 1"/>
      </material>
    </visual>
    <collision>
      <geometry>
        <mesh filename="package://sara_description/meshes/poignet_bas.STL" scale="0.001 0.001 0.001"/>
      </geometry>
      <origin rpy=" 0 1.5708 0" xyz="-0.02575  -0.01375 0.0305448"/>
    </collision>
  </link>
  <joint name="arm_low_wrist_grasp_socket_joint" type="revolute">
    <parent link="arm_low_wrist_link"/>
    <child link="arm_socket_link"/>
    <limit effort="1000.0" lower="-3.1416" upper="3.1416" velocity="0.5"/>
    <origin rpy="1.5708 0 0" xyz="0 0.084375 0"/>
    <axis xyz="1 0 0"/>
  </joint>
  <link name="arm_socket_link">
    <visual>
      <geometry>
        <mesh filename="package://sara_description/meshes/attache-pince.STL" scale="0.001 0.001 0.001"/>
      </geometry>
      <origin rpy="0 0 1.5708" xyz="0.028925 -0.025 -0.0362070"/>
      <material name="black">
        <color rgba="0.12 0.12 0.12 1"/>
      </material>
    </visual>
    <collision>
      <geometry>
        <mesh filename="package://sara_description/meshes/attache-pince.STL" scale="0.001 0.001 0.001"/>
      </geometry>
      <origin rpy="0 0 1.5708" xyz="0.028925 -0.025 -0.0362070"/>
    </collision>
  </link>
  <joint name="arm_end_effector_joint" type="fixed">
    <parent link="arm_socket_link"/>
    <child link="robotiq_85_base_link"/>
    <limit effort="1000.0" lower="-0.26" upper="0.26" velocity="0.5"/>
    <axis xyz="0 1 0"/>
    <origin rpy="0 1.5708 0" xyz="0 0 -0.02989"/>
  </joint>
  <link name="grasp_link">
    <visual>
      <geometry>
        <sphere radius="0.01"/>
      </geometry>
      <origin rpy="0 0 0" xyz="0 0.05 0"/>
    </visual>
    <inertial>
      <mass value="0"/>
      <origin rpy="0 0 0" xyz="0 0 0"/>
      <inertia ixx="0.001" ixy="0" ixz="0" iyy="0.001" iyz="0" izz="0.001"/>
    </inertial>
  </link>
  <joint name="grasp_joint" type="fixed">
    <parent link="robotiq_85_base_link"/>
    <child link="grasp_link"/>
    <origin rpy="3.1416 0 1.5708" xyz="0.075 0 -0.012"/>
  </joint>
  <gazebo reference="robotiq_85_base_link">
    <turnGravityOff>false</turnGravityOff>
  </gazebo>
  <gazebo reference="robotiq_85_left_knuckle_link">
    <turnGravityOff>false</turnGravityOff>
  </gazebo>
  <gazebo reference="robotiq_85_right_knuckle_link">
    <turnGravityOff>false</turnGravityOff>
  </gazebo>
  <gazebo reference="robotiq_85_left_finger_link">
    <turnGravityOff>false</turnGravityOff>
  </gazebo>
  <gazebo reference="robotiq_85_right_finger_link">
    <turnGravityOff>false</turnGravityOff>
  </gazebo>
  <gazebo reference="robotiq_85_left_inner_knuckle_link">
    <turnGravityOff>false</turnGravityOff>
  </gazebo>
  <gazebo reference="robotiq_85_right_inner_knuckle_link">
    <turnGravityOff>false</turnGravityOff>
  </gazebo>
  <gazebo reference="robotiq_85_left_finger_tip_link">
    <turnGravityOff>false</turnGravityOff>
  </gazebo>
  <gazebo reference="robotiq_85_right_finger_tip_link">
    <turnGravityOff>false</turnGravityOff>
  </gazebo>
  <link name="robotiq_85_base_link">
    <visual>
      <geometry>
        <mesh filename="package://sara_description/meshes/robotiq_c2/visual/robotiq_85_gripper_base.dae"/>
      </geometry>
      <origin rpy="3.1415 0 1.5707" xyz="0 0 0"/>
    </visual>
    <collision>
      <geometry>
        <mesh filename="package://sara_description/meshes/robotiq_c2/collision/robotiq_85_gripper_base.dae"/>
      </geometry>
      <origin rpy="1.5707 0 1.5707" xyz="0 0 0"/>
    </collision>
    <inertial>
      <mass value="0.1"/>
      <origin rpy="1.5708 0 1.5708" xyz="0 0 0"/>
      <inertia ixx="0.001" ixy="0" ixz="0" iyy="0.001" iyz="0" izz="0.001"/>
    </inertial>
  </link>
  <joint name="robotiq_85_left_knuckle_joint" type="revolute">
    <parent link="robotiq_85_base_link"/>
    <child link="robotiq_85_left_knuckle_link"/>
    <axis xyz="1 0 0"/>
    <origin rpy="-1.5707 1.5707 0" xyz=".04191 .0306 0"/>
    <limit effort="1000" lower="0" upper=".8575" velocity="2.0"/>
  </joint>
  <joint name="robotiq_85_right_knuckle_joint" type="revolute">
    <parent link="robotiq_85_base_link"/>
    <child link="robotiq_85_right_knuckle_link"/>
    <axis xyz="1 0 0"/>
    <origin rpy="1.5707 -1.5707 0" xyz=".04191 -.0306 0"/>
    <limit effort="1000" lower="0" upper="1.5707" velocity="2.0"/>
    <mimic joint="robotiq_85_left_knuckle_joint" multiplier="1"/>
  </joint>
  <link name="robotiq_85_left_knuckle_link">
    <visual>
      <geometry>
        <mesh filename="package://sara_description/meshes/robotiq_c2/visual/robotiq_85_gripper_joint_0_L.dae"/>
      </geometry>
      <origin rpy="3.14159 -1.5707 0" xyz="0 .04191 -.0306"/>
    </visual>
    <collision>
      <geometry>
        <mesh filename="package://sara_description/meshes/robotiq_c2/collision/robotiq_85_gripper_joint_0_L.dae"/>
      </geometry>
      <origin rpy="1.5707 -1.5707 0" xyz="0 .04191 -.0306"/>
    </collision>
    <inertial>
      <mass value="0.1"/>
      <origin rpy="1.5708 -1.5708 0" xyz="0 0 0"/>
      <inertia ixx="0.001" ixy="0" ixz="0" iyy="0.001" iyz="0" izz="0.001"/>
    </inertial>
  </link>
  <link name="robotiq_85_right_knuckle_link">
    <visual>
      <geometry>
        <mesh filename="package://sara_description/meshes/robotiq_c2/visual/robotiq_85_gripper_joint_0_R.dae"/>
      </geometry>
      <origin rpy="3.14159 1.5707 0" xyz="0 .04191 -.0306"/>
    </visual>
    <collision>
      <geometry>
        <mesh filename="package://sara_description/meshes/robotiq_c2/collision/robotiq_85_gripper_joint_0_R.dae"/>
      </geometry>
      <origin rpy="1.5707 1.5707 0" xyz="0 .04191 -.0306"/>
    </collision>
    <inertial>
      <mass value="0.1"/>
      <origin rpy="1.5708 1.5708 0" xyz="0 0 0"/>
      <inertia ixx="0.001" ixy="0" ixz="0" iyy="0.001" iyz="0" izz="0.001"/>
    </inertial>
  </link>
  <joint name="robotiq_85_left_finger_joint" type="fixed">
    <parent link="robotiq_85_left_knuckle_link"/>
    <child link="robotiq_85_left_finger_link"/>
    <axis xyz="1 0 0"/>
    <origin rpy="3.1415 0 0" xyz="0 .00508 .03134"/>
    <limit effort="1000" lower="0" upper="1.5707" velocity="2.0"/>
  </joint>
  <joint name="robotiq_85_right_finger_joint" type="fixed">
    <parent link="robotiq_85_right_knuckle_link"/>
    <child link="robotiq_85_right_finger_link"/>
    <axis xyz="1 0 0"/>
    <origin rpy="3.1415 0 0" xyz="0 .00508 .03134"/>
    <limit effort="1000" lower="0" upper="1.5707" velocity="2.0"/>
  </joint>
  <link name="robotiq_85_left_finger_link">
    <visual>
      <geometry>
        <mesh filename="package://sara_description/meshes/robotiq_c2/visual/robotiq_85_gripper_joint_1_L.dae"/>
      </geometry>
      <origin rpy="0 1.5707 0" xyz="0 -.03683 .06194"/>
    </visual>
    <collision>
      <geometry>
        <mesh filename="package://sara_description/meshes/robotiq_c2/collision/robotiq_85_gripper_joint_1_L.dae"/>
      </geometry>
      <origin rpy="-1.5707 1.5707 0" xyz="0 -.03683 .06194"/>
    </collision>
    <inertial>
      <mass value="0.1"/>
      <origin rpy="-1.5708 1.5708 0" xyz="0 0 0"/>
      <inertia ixx="0.001" ixy="0" ixz="0" iyy="0.001" iyz="0" izz="0.001"/>
    </inertial>
  </link>
  <link name="robotiq_85_right_finger_link">
    <visual>
      <geometry>
        <mesh filename="package://sara_description/meshes/robotiq_c2/visual/robotiq_85_gripper_joint_1_R.dae"/>
      </geometry>
      <origin rpy="0 -1.5707 0" xyz="0 -.03683 .06194"/>
    </visual>
    <collision>
      <geometry>
        <mesh filename="package://sara_description/meshes/robotiq_c2/collision/robotiq_85_gripper_joint_1_R.dae"/>
      </geometry>
      <origin rpy="-1.5707 -1.5707 0" xyz="0 -.03683 .06194"/>
    </collision>
    <inertial>
      <mass value="0.1"/>
      <origin rpy="-1.5707 -1.5707 0" xyz="0 0 0"/>
      <inertia ixx="0.001" ixy="0" ixz="0" iyy="0.001" iyz="0" izz="0.001"/>
    </inertial>
  </link>
  <joint name="robotiq_85_left_inner_knuckle_joint" type="revolute">
    <parent link="robotiq_85_base_link"/>
    <child link="robotiq_85_left_inner_knuckle_link"/>
    <axis xyz="1 0 0"/>
    <origin rpy="1.5707 1.5707 0" xyz=".04843 .0127 0"/>
    <limit effort="1000" lower="0" upper="1.5707" velocity="2.0"/>
    <mimic joint="robotiq_85_left_knuckle_joint" offset="0"/>
  </joint>
  <joint name="robotiq_85_right_inner_knuckle_joint" type="revolute">
    <parent link="robotiq_85_base_link"/>
    <child link="robotiq_85_right_inner_knuckle_link"/>
    <axis xyz="1 0 0"/>
    <origin rpy="-1.5707 -1.5707 0" xyz=".04843 -.0127 0"/>
    <limit effort="1000" lower="0" upper="1.5707" velocity="2.0"/>
    <mimic joint="robotiq_85_left_knuckle_joint" offset="0"/>
  </joint>
  <link name="robotiq_85_left_inner_knuckle_link">
    <visual>
      <geometry>
        <mesh filename="package://sara_description/meshes/robotiq_c2/visual/robotiq_85_gripper_joint_2_L.dae"/>
      </geometry>
      <origin rpy="0 1.5707 0" xyz="0 -.04843 .0127"/>
    </visual>
    <collision>
      <geometry>
        <mesh filename="package://sara_description/meshes/robotiq_c2/collision/robotiq_85_gripper_joint_2_L.dae"/>
      </geometry>
      <origin rpy="-1.5707 1.5707 0" xyz="0 -.04843 .0127"/>
    </collision>
    <inertial>
      <mass value="0.1"/>
      <origin rpy="-1.5707 1.5707 0" xyz="0 0 0"/>
      <inertia ixx="0.001" ixy="0" ixz="0" iyy="0.001" iyz="0" izz="0.001"/>
    </inertial>
  </link>
  <link name="robotiq_85_right_inner_knuckle_link">
    <visual>
      <geometry>
        <mesh filename="package://sara_description/meshes/robotiq_c2/visual/robotiq_85_gripper_joint_2_R.dae"/>
      </geometry>
      <origin rpy="0 -1.5707 0" xyz="0 -.04843 .0127"/>
    </visual>
    <collision>
      <geometry>
        <mesh filename="package://sara_description/meshes/robotiq_c2/collision/robotiq_85_gripper_joint_2_R.dae"/>
      </geometry>
      <origin rpy="-1.5707 -1.5707 0" xyz="0 -.04843 .0127"/>
    </collision>
    <inertial>
      <mass value="0.1"/>
      <origin rpy="-1.5707 -1.5707 0" xyz="0 0 0"/>
      <inertia ixx="0.001" ixy="0" ixz="0" iyy="0.001" iyz="0" izz="0.001"/>
    </inertial>
  </link>
  <joint name="robotiq_85_left_finger_tip_joint" type="revolute">
    <parent link="robotiq_85_left_inner_knuckle_link"/>
    <child link="robotiq_85_left_finger_tip_link"/>
    <axis xyz="1 0 0"/>
    <origin rpy="0 0 0" xyz="0 .04196 -.0388"/>
    <limit effort="1000" lower="0" upper="1.5707" velocity="2.0"/>
    <mimic joint="robotiq_85_left_knuckle_joint" multiplier="-1"/>
  </joint>
  <joint name="robotiq_85_right_finger_tip_joint" type="revolute">
    <parent link="robotiq_85_right_inner_knuckle_link"/>
    <child link="robotiq_85_right_finger_tip_link"/>
    <axis xyz="1 0 0"/>
    <origin rpy="0 0 0" xyz="0 .04196 -.0388"/>
    <limit effort="1000" lower="0" upper="1.5707" velocity="2.0"/>
    <mimic joint="robotiq_85_left_knuckle_joint" multiplier="-1"/>
  </joint>
  <link name="robotiq_85_left_finger_tip_link">
    <visual>
      <geometry>
        <mesh filename="package://sara_description/meshes/robotiq_c2/visual/robotiq_85_gripper_joint_3_L.dae"/>
      </geometry>
      <origin rpy="0 1.5707 0" xyz="0 -.090381 .051505"/>
    </visual>
    <collision>
      <geometry>
        <mesh filename="package://sara_description/meshes/robotiq_c2/collision/robotiq_85_gripper_joint_3_L.dae"/>
      </geometry>
      <origin rpy="-1.5707 1.5707 0" xyz="0 -.090381 .051505"/>
    </collision>
    <inertial>
      <mass value="0.1"/>
      <origin rpy="-1.5707 1.5707 0" xyz="0 0 0"/>
      <inertia ixx="0.001" ixy="0" ixz="0" iyy="0.001" iyz="0" izz="0.001"/>
    </inertial>
  </link>
  <link name="robotiq_85_right_finger_tip_link">
    <visual>
      <geometry>
        <mesh filename="package://sara_description/meshes/robotiq_c2/visual/robotiq_85_gripper_joint_3_R.dae"/>
      </geometry>
      <origin rpy="0 -1.5707 0" xyz="0 -.090381 .051505"/>
    </visual>
    <collision>
      <geometry>
        <mesh filename="package://sara_description/meshes/robotiq_c2/collision/robotiq_85_gripper_joint_3_R.dae"/>
      </geometry>
      <origin rpy="-1.5707 -1.5707 0" xyz="0 -.090381 .051505"/>
    </collision>
    <inertial>
      <mass value="0.1"/>
      <origin rpy="-1.5707 -1.5707 0" xyz="0 0 0"/>
      <inertia ixx="0.001" ixy="0" ixz="0" iyy="0.001" iyz="0" izz="0.001"/>
    </inertial>
  </link>
</robot>
