<?xml version="1.0"?>
<robot xmlns:xacro="http://www.ros.org/wiki/xacro">

    <xacro:macro name="sara_head" params="parent *origin sim">

        <xacro:if value="${sim}">
            <xacro:include filename="$(find sara_description)/urdf/head_v1/head.gazebo.xacro"/>
            <xacro:sara_head_gazebo/>
        </xacro:if>

        <joint name="head_pitch_joint" type="revolute">
            <parent link="${parent}_link"/>
            <child link="head_link"/>
            <limit effort="1000.0" lower="-1.3" upper="1.3" velocity="0.5"/>
            <xacro:insert_block name="origin"/>
            <axis xyz="0 0 1"/>
        </joint>

        <link name="head_link">
            <visual>
                <geometry>
                    <mesh filename="package://sara_description/meshes/tete.STL" scale="0.001 0.001 0.001"/>
                </geometry>
                <origin xyz="0 0 0" rpy="1.5708 -1.5708 1.5708"/>
                <material name="blue">
                    <color rgba="0.06 0.06 1 1"/>
                </material>
            </visual>
            <collision>
                <geometry>
                    <mesh filename="package://sara_description/meshes/tete.STL" scale="0.001 0.001 0.001"/>
                </geometry>
                <origin xyz="0 0 0" rpy="1.5708 -1.5708 1.5708"/>
            </collision>
            <inertial>
                <mass value="2.60401968"/>
                <origin xyz="0 0 0" rpy="1.5708 0 1.5708"/>
                <inertia ixx="0.02722768" ixy="0.00015673" ixz="0.0000148"
                         iyy="0.02716685" iyz="0.00524002"
                         izz="0.04109802"/>
            </inertial>
        </link>

    </xacro:macro>
</robot>
